Workbook

Sheet MORELIA_RP
A3: ACTIVIDAD | B3: Cuenta de ACTIVIDAD | C3: Suma de Numero de Agentes Participantes: | D3: Suma de Cantidad de Unidades Oficiales de Seguridad Vial: | E3: Suma de Kilómetros recorridos. | F3: Suma de Cantidad de Personas alcanzadas.
A4: APOYO A EVENTOS PÚBLICOS | B4: 1 | C4: 1 | D4: 1 | E4: 4 | F4: 400
A5: APOYO A LA VIALIDAD | B5: 1 | C5: 2 | D5: 0 | E5: 0 | F5: 100
A6: APOYOS A OTRAS DEPENDENCIAS (Publicas o privadas) | B6: 1 | C6: 6 | D6: 1 | E6: 15 | F6: 40
A7: BANCOS | B7: 1 | C7: 2 | D7: 1 | E7: 14 | F7: 0
A8: CORTES DE CIRCULACIÓN | B8: 6 | C8: 13 | D8: 6 | E8: 124 | F8: 570
A9: DILIGENCIAS | B9: 1 | C9: 2 | D9: 1 | E9: 1 | F9: 130
A10: ESCUELAS | B10: 14 | C10: 22 | D10: 5 | E10: 48 | F10: 4330
A11: OFICINAS GUBERNAMENTALES | B11: 2 | C11: 4 | D11: 1 | E11: 14 | F11: 20
A12: PASOS PEATONALES | B12: 1 | C12: 2 | D12: 0 | E12: 0 | F12: 15
A13: PATRULLAJES | B13: 7 | C13: 14 | D13: 7 | E13: 190 | F13: 600
A14: RECORRIDOS DE PROXIMIDAD | B14: 1 | C14: 1 | D14: 1 | E14: 25 | F14: 0
A15: SEGURIDAD EN CARRETERAS - SALAMANCA - MORELIA | B15: 1 | C15: 3 | D15: 1 | E15: 40 | F15: 100
... A19: Suma total | B19: 41 | C19: 82 | D19: 29 | E19: 581 | F19: 6405

Sheet JIQUILPAN_RP
A3: ACTIVIDAD | B3: Cuenta de ACTIVIDAD | C3: Suma de Numero de Agentes Participantes: | D3: Suma de Cantidad de Unidades Oficiales de Seguridad Vial: | E3: Suma de Kilómetros recorridos. | F3: Suma de Cantidad de Personas alcanzadas.
A4: AVENIDAS | B4: 2 | C4: 4 | D4: 2 | E4: 36 | F4: 14
A5: BANCOS | B5: 1 | C5: 3 | D5: 1 | E5: 12 | F5: 8
A6: CONCIENTIZACIÓN Y PREVENCIÓN | B6: 1 | C6: 3 | D6: 1 | E6: 0 | F6: 25
A7: ESCUELAS | B7: 4 | C7: 9 | D7: 4 | E7: 58 | F7: 101
A8: GASOLINERAS | B8: 3 | C8: 6 | D8: 3 | E8: 47 | F8: 27
A9: OBRAS PÚBLICAS | B9: 1 | C9: 1 | D9: 1 | E9: 21 | F9: 16
A10: OFICINAS GUBERNAMENTALES | B10: 2 | C10: 3 | D10: 2 | E10: 15 | F10: 23
A11: PERIFÉRICOS | B11: 1 | C11: 1 | D11: 1 | E11: 11 | F11: 10
A12: RECORRIDOS DE PROXIMIDAD | B12: 1 | C12: 2 | D12: 1 | E12: 15 | F12: 15
A13: TIENDAS DEPARTAMENTALES | B13: 1 | C13: 1 | D13: 1 | E13: 15 | F13: 7
A14: Suma total | B14: 17 | C14: 33 | D14: 17 | E14: 230 | F14: 246

Sheet ZAMORA_RP
A3: ACTIVIDAD | B3: Cuenta de ACTIVIDAD | C3: Suma de Numero de Agentes Participantes: | D3: Suma de Cantidad de Unidades Oficiales de Seguridad Vial: | E3: Suma de Kilómetros recorridos. | F3: Suma de Cantidad de Personas alcanzadas.
A4: ACCIDENTES | B4: 1 | C4: 1 | D4: 0 | E4: 30 | F4: 10
A5: APOYO A LA VIALIDAD | B5: 2 | C5: 4 | D5: 2 | E5: 6 | F5: 230
A6: APOYOS A OTRAS DEPENDENCIAS (Publicas o privadas) | B6: 1 | C6: 2 | D6: 1 | E6: 4 | F6: 0
A7: BANCOS | B7: 1 | C7: 2 | D7: 0 | E7: 2 | F7: 5
A8: CONCIENTIZACIÓN Y PREVENCIÓN | B8: 2 | C8: 4 | D8: 0 | E8: 2 | F8: 16
A9: ESCUELAS | B9: 11 | C9: 18 | D9: 7 | E9: 57 | F9: 450
A10: GASOLINERAS | B10: 1 | C10: 2 | D10: 1 | E10: 6 | F10: 0
A11: OFICINAS GUBERNAMENTALES | B11: 6 | C11: 13 | D11: 5 | E11: 27 | F11: 85
A12: PASOS PEATONALES | B12: 3 | C12: 6 | D12: 0 | E12: 3 | F12: 5
A13: PATRULLAJES | B13: 4 | C13: 9 | D13: 4 | E13: 67 | F13: 50
A14: PERIFÉRICOS | B14: 1 | C14: 2 | D14: 0 | E14: 5 | F14: 10
A15: RECORRIDOS DE PROXIMIDAD | B15: 1 | C15: 2 | D15: 0 | E15: 2 | F15: 10
... A18: Suma total | B18: 36 | C18: 70 | D18: 21 | E18: 214 | F18: 921

Sheet LA_PIEDAD_RP
A3: ACTIVIDAD | B3: Cuenta de ACTIVIDAD | C3: Suma de Numero de Agentes Participantes: | D3: Suma de Cantidad de Unidades Oficiales de Seguridad Vial: | E3: Suma de Kilómetros recorridos. | F3: Suma de Cantidad de Personas alcanzadas.
A4: ACOMPAÑAMIENTO A CARAVANAS U OTROS | B4: 1 | C4: 2 | D4: 0 | E4: 10 | F4: 70
A5: AVENIDAS | B5: 3 | C5: 7 | D5: 3 | E5: 36 | F5: 0
A6: CONCIENTIZACIÓN Y PREVENCIÓN | B6: 2 | C6: 6 | D6: 2 | E6: 18 | F6: 40
A7: ESCUELAS | B7: 6 | C7: 14 | D7: 3 | E7: 39 | F7: 90
A8: OFICINAS GUBERNAMENTALES | B8: 4 | C8: 8 | D8: 2 | E8: 19 | F8: 40
A9: PASOS PEATONALES | B9: 4 | C9: 9 | D9: 3 | E9: 19 | F9: 20
A10: PATRULLAJES | B10: 2 | C10: 4 | D10: 1 | E10: 23 | F10: 10
A11: PERIFÉRICOS | B11: 2 | C11: 4 | D11: 0 | E11: 24 | F11: 25
A12: REPARTICIÓN DE TRÍPTICOS | B12: 1 | C12: 1 | D12: 1 | E12: 15 | F12: 10
A13: Suma total | B13: 25 | C13: 55 | D13: 15 | E13: 203 | F13: 305

Sheet URUAPAN_RP
A3: ACTIVIDAD | B3: Cuenta de ACTIVIDAD | C3: Suma de Numero de Agentes Participantes: | D3: Suma de Cantidad de Unidades Oficiales de Seguridad Vial: | E3: Suma de Kilómetros recorridos. | F3: Suma de Cantidad de Personas alcanzadas.
A4: ACTOS DELICTIVOS | B4: 1 | C4: 1 | D4: 1 | E4: 30 | F4: 0
A5: ESCUELAS | B5: 7 | C5: 14 | D5: 7 | E5: 27 | F5: 1011
A6: GASOLINERAS | B6: 2 | C6: 2 | D6: 2 | E6: 10 | F6: 12
A7: OFICINAS GUBERNAMENTALES | B7: 2 | C7: 4 | D7: 2 | E7: 4 | F7: 12
A8: OTROS OPERATIVOS (Especificar en las novedades relevantes) | B8: 3 | C8: 4 | D8: 3 | E8: 20 | F8: 30
A9: PERIFÉRICOS | B9: 2 | C9: 2 | D9: 2 | E9: 12 | F9: 9
A10: Suma total | B10: 17 | C10: 27 | D10: 17 | E10: 103 | F10: 1074

Sheet APATZINGAN_RP
A3: ACTIVIDAD | B3: Cuenta de ACTIVIDAD | C3: Suma de Numero de Agentes Participantes: | D3: Suma de Cantidad de Unidades Oficiales de Seguridad Vial: | E3: Suma de Kilómetros recorridos. | F3: Suma de Cantidad de Personas alcanzadas.
A4: APOYO A LA VIALIDAD | B4: 1 | C4: 3 | D4: 2 | E4: 20 | F4: 0
A5: CONCIENTIZACIÓN USO DE CASCO | B5: 1 | C5: 1 | D5: 1 | E5: 1 | F5: 23
A6: CORTES DE CIRCULACIÓN | B6: 1 | C6: 1 | D6: 1 | E6: 20 | F6: 0
A7: ESCUELAS | B7: 6 | C7: 10 | D7: 6 | E7: 48 | F7: 0
A8: OFICINAS GUBERNAMENTALES | B8: 3 | C8: 5 | D8: 3 | E8: 16 | F8: 0
A9: PASOS PEATONALES | B9: 2 | C9: 2 | D9: 1 | E9: 1 | F9: 0
A10: PATRULLAJES | B10: 3 | C10: 5 | D10: 3 | E10: 44 | F10: 0
A11: RECORRIDOS DE PROXIMIDAD | B11: 1 | C11: 2 | D11: 1 | E11: 10 | F11: 45
A12: REPARTICIÓN DE TRÍPTICOS | B12: 2 | C12: 4 | D12: 3 | E12: 21 | F12: 90
A13: VÍAS FÉRREAS | B13: 1 | C13: 2 | D13: 1 | E13: 4 | F13: 0
A14: Suma total | B14: 21 | C14: 35 | D14: 22 | E14: 185 | F14: 158

Sheet HUETAMO_RP
A3: ACTIVIDAD | B3: Cuenta de ACTIVIDAD | C3: Suma de Numero de Agentes Participantes: | D3: Suma de Cantidad de Unidades Oficiales de Seguridad Vial: | E3: Suma de Kilómetros recorridos. | F3: Suma de Cantidad de Personas alcanzadas.
A4: APOYO A LA VIALIDAD | B4: 1 | C4: 2 | D4: 1 | E4: 1 | F4: 0
A5: BANCOS | B5: 3 | C5: 3 | D5: 1 | E5: 0 | F5: 77
A6: CONCIENTIZACIÓN USO DE CASCO | B6: 1 | C6: 2 | D6: 1 | E6: 2 | F6: 18
A7: CONCIENTIZACIÓN Y PREVENCIÓN | B7: 1 | C7: 2 | D7: 1 | E7: 2 | F7: 19
A8: CORTES DE CIRCULACIÓN | B8: 1 | C8: 2 | D8: 1 | E8: 2 | F8: 50
A9: ESCUELAS | B9: 4 | C9: 5 | D9: 1 | E9: 2 | F9: 93
A10: OFICINAS GUBERNAMENTALES | B10: 4 | C10: 5 | D10: 2 | E10: 1 | F10: 22
A11: PASOS PEATONALES | B11: 2 | C11: 2 | D11: 0 | E11: 0 | F11: 8
A12: RECORRIDOS DE PROXIMIDAD | B12: 1 | C12: 2 | D12: 1 | E12: 40 | F12: 20
A13: Suma total | B13: 18 | C13: 25 | D13: 9 | E13: 50 | F13: 307

Sheet COALCOMAN_RP
A3: ACTIVIDAD | B3: Cuenta de ACTIVIDAD | C3: Suma de Numero de Agentes Participantes: | D3: Suma de Cantidad de Unidades Oficiales de Seguridad Vial: | E3: Suma de Kilómetros recorridos. | F3: Suma de Cantidad de Personas alcanzadas.
A4: ESCUELAS | B4: 5 | C4: 5 | D4: 3 | E4: 13 | F4: 0
A5: OFICINAS GUBERNAMENTALES | B5: 1 | C5: 1 | D5: 0 | E5: 0 | F5: 0
A6: PATRULLAJES | B6: 2 | C6: 3 | D6: 2 | E6: 57 | F6: 0
A7: RECORRIDOS DE PROXIMIDAD | B7: 1 | C7: 2 | D7: 0 | E7: 0 | F7: 19
A8: Suma total | B8: 9 | C8: 11 | D8: 5 | E8: 70 | F8: 19

Sheet ZITACUARO_RP
A3: ACTIVIDAD | B3: Cuenta de ACTIVIDAD | C3: Suma de Numero de Agentes Participantes: | D3: Suma de Cantidad de Unidades Oficiales de Seguridad Vial: | E3: Suma de Kilómetros recorridos. | F3: Suma de Cantidad de Personas alcanzadas.
A4: AMPLIACION CARRETERA CIUIDAD HIDALGO-ZITACUARO | B4: 2 | C4: 8 | D4: 2 | E4: 34 | F4: 0
A5: APOYO A EVENTOS RELIGIOSOS | B5: 1 | C5: 1 | D5: 0 | E5: 0 | F5: 0
A6: CONCIENTIZACIÓN USO DE CASCO | B6: 1 | C6: 4 | D6: 1 | E6: 6 | F6: 32
A7: CONCIENTIZACIÓN Y PREVENCIÓN | B7: 1 | C7: 4 | D7: 1 | E7: 8 | F7: 27
A8: CORTES DE CIRCULACIÓN | B8: 1 | C8: 4 | D8: 1 | E8: 8 | F8: 50
A9: ESCUELAS | B9: 10 | C9: 25 | D9: 8 | E9: 87 | F9: 172
A10: OBRAS PÚBLICAS | B10: 1 | C10: 3 | D10: 1 | E10: 18 | F10: 0
A11: OFICINAS GUBERNAMENTALES | B11: 7 | C11: 18 | D11: 8 | E11: 68 | F11: 30
A12: PATRULLAJES | B12: 5 | C12: 17 | D12: 5 | E12: 105 | F12: 15
A13: PERIFÉRICOS | B13: 2 | C13: 2 | D13: 2 | E13: 18 | F13: 0
A14: RECORRIDOS DE PROXIMIDAD | B14: 3 | C14: 11 | D14: 3 | E14: 32 | F14: 50
A15: REPARTICIÓN DE TRÍPTICOS | B15: 2 | C15: 8 | D15: 2 | E15: 15 | F15: 52
... A17: Suma total | B17: 37 | C17: 110 | D17: 35 | E17: 408 | F17: 428

Sheet LAZARO_CARDENAS_RP
A3: ACTIVIDAD | B3: Cuenta de ACTIVIDAD | C3: Suma de Numero de Agentes Participantes: | D3: Suma de Cantidad de Unidades Oficiales de Seguridad Vial: | E3: Suma de Kilómetros recorridos. | F3: Suma de Cantidad de Personas alcanzadas.
A4: BASES DE OPERACIONES INTERINSTITUCIONAL | B4: 2 | C4: 2 | D4: 2 | E4: 12 | F4: 35
A5: CONCIENTIZACIÓN USO DE CASCO | B5: 1 | C5: 2 | D5: 1 | E5: 15 | F5: 20
A6: CONCIENTIZACIÓN Y PREVENCIÓN | B6: 2 | C6: 4 | D6: 2 | E6: 15 | F6: 26
A7: ESCUELAS | B7: 7 | C7: 10 | D7: 20 | E7: 251 | F7: 470
A8: OFICINAS GUBERNAMENTALES | B8: 1 | C8: 1 | D8: 1 | E8: 15 | F8: 20
A9: PASOS PEATONALES | B9: 1 | C9: 1 | D9: 1 | E9: 1 | F9: 50
A10: PATRULLAJES | B10: 2 | C10: 3 | D10: 2 | E10: 17 | F10: 20
A11: Suma total | B11: 16 | C11: 23 | D11: 29 | E11: 326 | F11: 641

Sheet UNIFICADA
A1: ID_Folio | B1: Folio | C1: Region y Delegación. | D1: ACTIVIDAD | E1: Fecha: | F1: Hora: | G1: GPS | H1: Dirección o Referencia de la Ubicación: | I1: Tarjeta informativa (WhatsApp) | J1: Foto 1/2 | K1: Foto 2/2 | L1: Cantidad de Personas alcanzadas. | M1: Numero de Agentes Participantes: | N1: Nombre de Los Agentes de Seguridad Vial Participantes: | O1: Cantidad de Unidades Oficiales de Seguridad Vial: | P1: Numero Económico de las Unidades Participantes. | Q1: Kilómetros recorridos. | R1: User_ID | S1: REGIÓN | T1: TIPO DE REPORTE
A2: ac3870b2 | B2: ac3870b2 | C2: HUETAMO - NOCUPETARO | D2: RECORRIDOS DE PROXIMIDAD | E2: 46128 | F2: 0.73659722 | I2: *Guardia Civil* *Agrupamiento de Seguridad Vial* *Region Huetamo* *Delegación No. 50 Nocupetaro* *Jueves 16 de Abril de 2026* *Asunto: Recorrido en Disuasión del Delito ( Carreteras Seguras)* *17:30 horas* Para conocimiento del mando superior me permito informar que se continúa con los Recorridos sobre las carreteras estatales y vías Públicas dentro de esta jurisdicción haciendo acto de presencia y dando seguridad Vial a los Automovilistas y peatones ,sin novedad relevante hasta el momento. Informa la Unidad 04-350 (prestada del municipio) a cargo de los oficiales : Gustavo Calderón Gordillo y Reynaldo Mendez Ortega Reporto .Cmte. Jose Carmen Mondragón Posadas Encargado, de la Delegación de Seguridad Vial de Nocupetaro | J2: PROXIMIDAD SOCIAL_Images/ac3870b2.Foto 1-2.234138.jpg | K2: PROXIMIDAD SOCIAL_Images/ac3870b2.Foto 2-2.234138.jpg | L2: 20 | M2: 2 | O2: 1 | P2: 0 | Q2: 40 | R2: NOCUPETARO | S2: HUETAMO | T2: PROXIMIDAD SOCIAL
A3: 2f28bc3f | B3: 2f28bc3f | C3: COALCOMAN - COALCOMAN | D3: RECORRIDOS DE PROXIMIDAD | E3: 46128 | F3: 0.81030093 | I3: *Guardia Civil* *Unidad dé Delegaciones* *Región Coalcoman* *Delegación 030 Coalcoman* *Jueves 16 de abril del 2026. 19:25 horas. *Asunto:* Proximidad social. Me permito informar a mi superioridad, que el personal de está delegación de seguridad vial, nos encontramos realizando la proximidad Social entre la sociedad en la zona centro. Personas alcanzadas 19 *Elementos participantes* 1.- Leonardo Rolón Meraz (responsable) 2-.Sergio Suárez Jiménez. *Pie tierra* Lo que me permito informar . Respetuosamente. Integrante de la Coordinación de Seguridad Vial Estatal delegación Coalcoman 030 región Coalcoman Cmte. Leonardo Rolón Meraz. | J3: PROXIMIDAD SOCIAL_Images/2f28bc3f.Foto 1-2.012921.jpg | K3: PROXIMIDAD SOCIAL_Images/2f28bc3f.Foto 2-2.012921.jpg | L3: 19 | M3: 2 | N3: Leonardo Rolon Meraz (Responsable) Y Sérgio Suárez Jiménez. | O3: 0 | P3: 0 | Q3: 0 | R3: 11 | S3: COALCOMAN | T3: PROXIMIDAD SOCIAL
A4: e4fab872 | B4: e4fab872 | C4: JIQUILPAN - VENUSTIANO CARRANZA | D4: RECORRIDOS DE PROXIMIDAD | E4: 46128 | F4: 0.83016204 | I4: *G U A R D I A C I V I L* *COORDINACIÓN DEL AGRUPAMIENTO DE SEGURIDAD VIAL* *UNIDAD DE DELEGACIONES* *REGIÓN JIQUILPAN* *DELEGACIÓN 53 VENUSTIANO CARRANZA* *JUEVES 16 DE ABRIL DEL 2026* *18:00 HORAS* *Asunto:* Proximidad social Se informa que se realizan recorridos de Proximidad social en la cabecera municipal del municipio de venustiano Carranza *Unidad:* 04-181 *Kilómetros:* 10 Es lo que me permito a usted informar para su superior conocimiento quedando *sin novedad*. Reporta el encargado de la Delegación Jose de Jesús Alvarez Fernández de la coordinación del Agrupamiento de Seguridad Vial. | J4: PROXIMIDAD SOCIAL_Images/e4fab872.Foto 1-2.015633.jpg | K4: PROXIMIDAD SOCIAL_Images/e4fab872.Foto 2-2.015633.jpg | L4: 15 | M4: 2 | O4: 1 | P4: 0 | Q4: 15 | R4: 45 | S4: JIQUILPAN | T4: PROXIMIDAD SOCIAL
A5: 1e46b96d | B5: 1e46b96d | C5: ZITACUARO - ZITACUARO | D5: RECORRIDOS DE PROXIMIDAD | E5: 46128 | F5: 0.84559028 | I5: G U A R D I A C I V I L COORDINACIÓN DEL AGRUPAMIENTO DE SEGURIDAD VIAL UNIDAD DE DELEGACIONES REGIÓN ZITACUARO DELEGACIÓN 10 ZITÁCUARO JUEVES 16 DE MARZO DE 2026 Asunto: Proximidad social. Por medio de la presente se informa que se continúa con la campaña de Proximidad Social con el Tema Trabajando Unidos para proteger la integridad de todas y todos, donde se realizan recorridos de prevencion del delito en plazas y centros comerciales de prevención, los cuales se llevan a cabo sin novedad. Personas concientizadas (20) A cargo Diana Marín Colín Elementos de apoyo Lázaro Bernal Marín Marisol Hernández Vieyra Luis Alonso Jerónimo Enoc Martínez Rogel Unidad: 19-3978 Kilometros: 6 Reporta el encargado de la Delegación 10 Zitácuaro de la Coordinación del Agrupamiento de Seguridad Vial. Cmte. José María Mendoza Farías. | J5: PROXIMIDAD SOCIAL_Images/1e46b96d.Foto 1-2.021951.jpg | K5: PROXIMIDAD SOCIAL_Images/1e46b96d.Foto 2-2.021951.jpg | L5: 20 | M5: 5 | O5: 1 | P5: 0 | Q5: 6 | R5: 35 | S5: ZITACUARO | T5: PROXIMIDAD SOCIAL
A6: 212ecbed | B6: 212ecbed | C6: ZAMORA - ECUANDUREO | D6: RECORRIDOS DE PROXIMIDAD | E6: 46128 | F6: 0.96090278 | I6: G U A R D I A C I V I L COORDINACIÓN DEL AGRUPAMIENTO DE SEGURIDAD VIAL UNIDAD DE DELEGACIONES REGIÓN ZAMORA DELEGACIÓN ECUANDUREO JUEVES 16 DE ABRIL DE 2026 15:00 HORAS Asunto: Recorridos de Proximidad Social Por medio de la presente se informa a la superioridad que se dan Recorridos de Vigilancia en las Tiendas con la finalidad de dar Presencia y fomentar la proximidad social y prevenir el delito Informa Miguel Ramírez Julián y Marco Antonio Félix Flores de la Delegación de Seguridad Vial Ecuandureo Reporta el encargado de la Delegación Miguel Ramírez Julián de la coordinación del Agrupamiento de Seguridad Vial | J6: PROXIMIDAD SOCIAL_Images/212ecbed.Foto 1-2.050416.jpg | K6: PROXIMIDAD SOCIAL_Images/212ecbed.Foto 2-2.050416.jpg | L6: 10 | M6: 2 | O6: 0 | P6: 0 | Q6: 2 | R6: 31 | S6: ZAMORA | T6: PROXIMIDAD SOCIAL
A7: da388de7 | B7: da388de7 | C7: APATZINGAN - APATZINGAN | D7: RECORRIDOS DE PROXIMIDAD | E7: 46129 | F7: 0.39748843 | I7: *G U A R D I A C I V I L* *COORDINACIÓN DEL AGRUPAMIENTO DE SEGURIDAD VIAL* *UNIDAD DE DELEGACIONES* *REGIÓN APATZINGÁN* *DELEGACIÓN 07 APATZINGÁN* *Viernes 17 DE ABRIL DEL 2026* *Asunto:* Proximidad social *09:30 HORAS* *Coordenadas:* 19.086585,-102.354554 Por medio de la presente me permito Informar a usted que esta delegación de seguridad vial continúa con las actividades de próximidad social en los establecimientos y negocios de esta ciudad, haciéndoles del conocimiento los números de emergencia. *Elementos de la delegación* Unidades 24-7682 01.- Policía Raúl Dimas Nava 02.- Policía Griselda Wences Reporta el encargado de la Delegación Apatzingán de la coordinación del Agrupamiento de Seguridad Vial Cmte. Julio Duvalier Hernández De la Cruz. | J7: PROXIMIDAD SOCIAL_Images/da388de7.Foto 1-2.153307.jpg | K7: PROXIMIDAD SOCIAL_Images/da388de7.Foto 2-2.153307.jpg | L7: 45 | M7: 2 | O7: 1 | P7: 0 | Q7: 10 | R7: 13 | S7: APATZINGAN | T7: PROXIMIDAD SOCIAL
A8: bf7d7511 | B8: bf7d7511 | C8: ZITACUARO - ZITACUARO | D8: RECORRIDOS DE PROXIMIDAD | E8: 46129 | F8: 0.45701389 | I8: G U A R D I A C I V I L COORDINACIÓN DEL AGRUPAMIENTO DE SEGURIDAD VIAL UNIDAD DE DELEGACIONES REGIÓN ZITACUARO DELEGACIÓN 10 ZITÁCUARO VIERNES 17 DE MARZO DE 2026 Asunto: Proximidad social. Por medio de la presente se informa que se continúa con la campaña de Proximidad Social con el Tema Trabajando Unidos para proteger la integridad de todas y todos, donde se realizan recorridos de prevencion del delito en plazas y centros comerciales de prevención, los cuales se llevan a cabo sin novedad. Personas concientizadas (20) A cargo Marisol Hernández Vieyra Elemento de apoyo Lázaro Bernal Marin Luis Alonso Jerónimo Enoc Martínez Rogel Unidad: 19-3978 Kilometros: 6 Reporta el encargado de la Delegación 10 Zitácuaro de la Coordinación del Agrupamiento de Seguridad Vial. Cmte. José María Mendoza Farias | J8: PROXIMIDAD SOCIAL_Images/bf7d7511.Foto 1-2.165950.jpg | K8: PROXIMIDAD SOCIAL_Images/bf7d7511.Foto 2-2.165950.jpg | L8: 20 | M8: 4 | O8: 1 | P8: 0 | Q8: 6 | R8: 35 | S8: ZITACUARO | T8: PROXIMIDAD SOCIAL
A9: be085393 | B9: be085393 | C9: ZITACUARO - CIUDAD HIDALGO | D9: RECORRIDOS DE PROXIMIDAD | E9: 46129 | F9: 0.55762731 | I9: GUARDIA CIVIL COORDINACIÓN DEL AGRUPAMIENTO DE SEGURIDAD VIAL UNIDAD DE DELEGACIONES REGIÓN ZITÁCUARO DELEGACIÓN 09 CIUDAD HIDALGO VIERNES 17 DE ABRIL DE 2026 13:15 HORAS Asunto: Proximidad social. Para conocimiento de los mandos, se informa que se continúa con la campaña de proximidad social con el tema “Trabajando unidos para proteger la integridad de todas y todos”, realizando recorridos de prevención del delito en plazas y comercios de la zona centro de este municipio.Seguridad Vial de Ciudad Hidalgo lleva a cabo dichas actividades sin novedad. A cargo de los agentes de Seguridad Vial: el suscrito y Paulina Viridiana Mondragón Alanis. a bordo de la unidad 03-641 Kilometraje recorrido: 20 Personas alcanzadas: 10 Reporta el encargado de la delegación:Cmdte. Jesús Benito Vázquez Chávez, de la Coordinación del Agrupamiento de Seguridad Vial. | J9: PROXIMIDAD SOCIAL_Images/be085393.Foto 1-2.195538.jpg | K9: PROXIMIDAD SOCIAL_Images/be085393.Foto 2-2.195538.jpg | L9: 10 | M9: 2 | O9: 1 | P9: 0 | Q9: 20 | R9: 38 | S9: ZITACUARO | T9: PROXIMIDAD SOCIAL
A10: f0171461 | B10: f0171461 | C10: MORELIA - ACUITZIO DEL CANJE | D10: RECORRIDOS DE PROXIMIDAD | E10: 46129 | F10: 0.61744213 | I10: GUARDIA CIVIL COORDINACIÓN DE AGRUPAMIENTOS DE SEGURIDAD VIAL UNIDAD DE DELEGACIONES DELEGACION 043 ACUITZIO DEL CANJE VIERNES 17 DE ABRIL DE 2026 14:00 HORAS TARJETA INFORMATIVA ASUNTO: RECORRIDO EN CARRETERAS Por medio de la presente informo que a bordo de la CRP 23-0923 se dan recorridos de seguridad y vigilancia en la Carretera- Pátzcuaro Morelia kilometro 26+000 se encuentra sin novedad 25 km recorridos Reporta el encargado de la Delegación 043 Acuitzio del Canje Pol. Primero Roberto Carlos Duarte Báez de la Coordinación del Agrupamiento de Seguridad Vial. | J10: PROXIMIDAD SOCIAL_Images/f0171461.Foto 1-2.205044.jpg | K10: PROXIMIDAD SOCIAL_Images/f0171461.Foto 2-2.205044.jpg | L10: 0 | M10: 1 | O10: 1 | P10: 0 | Q10: 25 | R10: 23 | S10: MORELIA | T10: PROXIMIDAD SOCIAL
A11: 6a52176c | B11: 6a52176c | C11: LAZARO CARDENAS - ARTEAGA | D11: CONCIENTIZACIÓN Y PREVENCIÓN | E11: 46128 | F11: 0.74136574 | G11: RESPETA LOS LIMITES DE VELOCIDAD | I11: *Actividades* 14-04-2026 Se implementa el dispositivo vial *escuela segura* a la entrada y salida de los diferentes centros educativos de esta cabecera Mpal. * *Sin noveda* Se realizan recorridos dentro y fuera de la población en la unidad 04-153 con la finalidad de prevenir hechos de tránsito,prevención del delito y asistencia a la ciudadanía. *Sin novedad* Se monitorean oficinas gubernamentales como son: *Presidencia Municipal *Administración de Rentas *Registro Civil *Juzgado Mixto de primera instancia *Laborando sin novedad* Se entregan Trípticos de información para concientización y prevencion de hechos de tránsito con la leyenda *por tu seguridad y la de todos* Se realizan recorridos nocturnos en la unidad 04-153 para la prevención y disuasión de algun hecho delictivo sobre las diferentes calles y avenidas de la poblacion. *Sin novedad* | J11: CAMPAÑAS_Images/6a52176c.Foto 1-2.234910.jpg | K11: CAMPAÑAS_Images/6a52176c.Foto 2-2.234910.jpg | L11: 6 | M11: 2 | O11: 1 | P11: 0 | Q11: 0 | R11: 10 | S11: LAZARO CARDENAS | T11: CAMPAÑAS
A12: cca42424 | B12: cca42424 | C12: JIQUILPAN - JIQUILPAN | D12: CONCIENTIZACIÓN Y PREVENCIÓN | E12: 46128 | F12: 0.75353009 | G12: USO DE CASCO | I12: *G U A R D I A C I V I L* *COORDINACIÓN DEL AGRUPAMIENTO DE SEGURIDAD VIAL* *UNIDAD DE DELEGACIONES* *REGIÓN JIQUILPAN* *DELEGACIÓN 05 JIQUILPAN* *JUEVES 16 DE ABRIL DEL 2026* *17:50 HORAS* Asunto: Campaña de concientización de uso de casco Se informa a la superioridad que se realizó dispositivo de *concientización y sensibilización para el uso de casco* sobre la carretera Jiquilpan-Sahuayo a la altura del entronque con la avenida Universidad. Asi mismo quedamos pendientes para informar cualquier novedad de relevancia. Se realiza la función en la Unidad 03-600, a cargo del oficial Luis Alejandro Gomez Vilchis, con 02 elementos más. Reporta el Encargado de la Delegación, Jesús Manuel Martínez Ochoa, de la Coordinación del Agrupamiento de Seguridad Vial | J12: CAMPAÑAS_Images/cca42424.Foto 1-2.000556.jpg | K12: CAMPAÑAS_Images/cca42424.Foto 2-2.000556.jpg | L12: 25 | M12: 3 | O12: 1 | P12: 0 | Q12: 0 | R12: 41 | S12: JIQUILPAN | T12: CAMPAÑAS
A13: 84fc5dbc | B13: 84fc5dbc | C13: HUETAMO - NOCUPETARO | D13: CONCIENTIZACIÓN Y PREVENCIÓN | E13: 46128 | F13: 0.7825 | G13: UTILIZA EL CINTURON DE SEGURIDAD | I13: Guardia Civil Seguridad Vial Región Huetamo Delegación 50 Nocupetaro Asunto: Campaña de Concientización Jueves 16/04/2026 18:10 horas Para conocimiento de la superioridad, se informa que se realiza entrega de trípticos alusivos a los automovilistas, con los temas de, Uso del cinturón de seguridad esto con la finalidad de concientizar a los conductores y prevenir hechos de transito con resultados fatales. Personas alcanzadas 16 Informa unidad 04-350 a cargo del oficial Gustavo Calderón Gordillo.y Reynaldo Méndez Ortega Reportó el Cmte. Jose Carmen Mondragon Posadas Encargado de la Delegacion de Seguridad Vial Estatal Nocupetaro. | J13: CAMPAÑAS_Images/84fc5dbc.Foto 1-2.004757.jpg | K13: CAMPAÑAS_Images/84fc5dbc.Foto 2-2.004757.jpg | L13: 19 | M13: 2 | O13: 1 | P13: 0 | Q13: 2 | R13: NOCUPETARO | S13: HUETAMO | T13: CAMPAÑAS
A14: 7967502e | B14: 7967502e | C14: APATZINGAN - GABRIEL ZAMORA | D14: REPARTICIÓN DE TRÍPTICOS | E14: 46128 | F14: 0.81167824 | G14: UTILIZA EL CINTURON DE SEGURIDAD | I14: *G U A R D I A C I V I L* *COORDINACIÓN DEL AGRUPAMIENTO DE SEGURIDAD VIAL* *UNIDAD DE DELEGACIONES* *REGION APATZINGAN* *DELEGACIÓN 40 GABRIEL ZAMORA* *JUEVES 16 DE ABRIL DEL 2026.* *13:30 horas* *Asunto*:Campaña *Conductor Responsable* Guardia Civil "Seguridad Vial" Informa que se inicia con la campaña concientización para los conductores haciendo las recomendaciones pertinentes para la prevencion de accidentes, sobre la importancia del uso del cinturon de seguridad, respetar los límites de velocidad, evitar el uso de celular mientras maneja, y evitar conducir en estado de ebriedad ya que de ello depende la seguridad de los pasajeros abordo del vehículo. En el lugar Samantha Estela Ruiz Soto Reporta el Encargado de la delegación No. 40 Gabriel Zamora, Julio Cesar Silva Mendoza de la coordinación del agrupamiento de seguridad vial. | J14: CAMPAÑAS_Images/7967502e.Foto 1-2.013013.jpg | K14: CAMPAÑAS_Images/7967502e.Foto 2-2.013013.jpg | L14: 20 | M14: 1 | O14: 1 | P14: 0 | Q14: 1 | R14: 15 | S14: APATZINGAN | T14: CAMPAÑAS
A15: ac064af3 | B15: ac064af3 | C15: APATZINGAN - APATZINGAN | D15: REPARTICIÓN DE TRÍPTICOS | E15: 46129 | F15: 0.45305556 | G15: USO DE CASCO | I15: *G U A R D I A C I V I L* *COORDINACIÓN DEL AGRUPAMIENTO DE SEGURIDAD VIAL* *UNIDAD DE DELEGACIONES* *REGIÓN APATZINGÁN* *DELEGACIÓN APATZINGÁN* *VIERNES 17 DE ABRIL DE 2026* *10:40 HORAS* *Asunto:* Entrega de trípticos y perifoneo (Motociclista Responsable) Por medio de la presente me permito Informar a usted que esta delegación de seguridad vial, informa que se continúa con la campaña preventiva *Motociclista responsable utiliza el casco, no moto sardina* para la concientización, la regularización y prevención de accidentes en motocicleta, Sobre la Av. Constitución de esta ciudad, con la entrega de volantes alusivos y perifoneo. *Reporta* Unidades 24-7682, 04-157 01.- Policía Angel David Alejandre Tejeda 02.- Policía Adrian Alejandro Valle Vázquez 03.- Policía Raul Dimas Nava Reporta el encargado de la Delegación de Apatzingán de la coordinación del Agrupamiento de Seguridad Vial Julio Duvalier Hernández de la Cruz | J15: CAMPAÑAS_Images/ac064af3.Foto 1-2.165325.jpg | K15: CAMPAÑAS_Images/ac064af3.Foto 2-2.165325.jpg | L15: 70 | M15: 3 | O15: 2 | P15: 0 | Q15: 20 | R15: 13 | S15: APATZINGAN | T15: CAMPAÑAS
A16: f8a66913 | B16: f8a66913 | C16: LA PIEDAD - LA PIEDAD | D16: CONCIENTIZACIÓN Y PREVENCIÓN | E16: 46129 | F16: 0.45951389 | G16: UTILIZA EL CINTURON DE SEGURIDAD | I16: *GUARDIA CIVIL* *COORDINACIÓN DEL AGRUPAMIENTO DE SEGURIDAD VIAL* *UNIDAD DE DELEGACIÓNES* *REGION LA PIEDAD* *DELEGACIÓN LA PIEDAD* *VIERNES 17 DE ABRIL DE 2026* *10:40 HORAS* *ASUNTO:* Campaña prevención y concientización Por medio de la presente me permito informar que se da cumplimiento a las órdenes giradas por la superioridad, se realiza proximidad social, realizando entrega de trípticos con la leyenda *Utiliza cinturón de Seguridad* esto con la finalidad de crear conciencia y dar a conocer un poco las obligaciones q tenemos como conductores. Informa la Unidad 3405 a cargo del Pol. Arturo Buenrostro Rodríguez de la Delegación de Seguridad Vial de La Piedad. Reporta el encargado de la Delegación Pol. 2° J. Jesús Arévalo León de la coordinación del Agrupamiento de Seguridad Vial. | J16: CAMPAÑAS_Images/f8a66913.Foto 1-2.170217.jpg | K16: CAMPAÑAS_Images/f8a66913.Foto 2-2.170217.jpg | L16: 19 | M16: 3 | O16: 1 | P16: 0 | Q16: 10 | R16: 4 | S16: LA PIEDAD | T16: CAMPAÑAS
A17: 9680fcf2 | B17: 9680fcf2 | C17: ZITACUARO - ZITACUARO | D17: REPARTICIÓN DE TRÍPTICOS | E17: 46129 | F17: 0.47765046 | G17: UTILIZA EL CINTURON DE SEGURIDAD | I17: G U A R D I A C I V I L COORDINACIÓN DEL AGRUPAMIENTO DE SEGURIDAD VIAL UNIDAD DE DELEGACIONES REGIÓN ZITACUARO DELEGACIÓN 10 ZITÁCUARO MIÉRCOLES 17 DE ABRIL DEL 2026 Asunto: Reparticion de trípticos. Me permito informar para su superior conocimiento, se realiza el Operativo de prevención de hechos de tránsito entregando trípticos con las recomendaciones "USO OBLIGATORIO DEL CINTURÓN DE SEGURIDAD Y RECOMENDACIONES DE SEGURIDAD VIAL" en las vías públicas. Sin novedad. USO DEL CINTURON DE SEGURIDAD Personas concientizadas (20) A cargo: Marisol Hernández Vieyra Elementos de apoyo: Lázaro Bernal Marin Enoc Martinez rogel Juan Alonso Jeronimo Unidad: 3180 Kilómetro: 9. Reporta el encargado de la Delegación 10 Zitácuaro de la coordinación de agrupamiento de Seguridad Vial. Cmte. José María Mendoza Farías. | J17: CAMPAÑAS_Images/9680fcf2.Foto 1-2.172855.jpg | K17: CAMPAÑAS_Images/9680fcf2.Foto 2-2.172855.jpg | L17: 20 | M17: 4 | O17: 1 | P17: 0 | Q17: 9 | R17: 35 | S17: ZITACUARO | T17: CAMPAÑAS
A18: d09f8588 | B18: d09f8588 | C18: ZITACUARO - ZITACUARO | D18: REPARTICIÓN DE TRÍPTICOS | E18: 46129 | F18: 0.47888889 | G18: USO DE CASCO | I18: G U A R D I A C I V I L COORDINACIÓN DEL AGRUPAMIENTO DE SEGURIDAD VIAL UNIDAD DE DELEGACIONES REGIÓN ZITÁCUARO DELEGACIÓN 10 ZITÁCUARO VIERNES 17 ABRIL DEL 2026 Asunto: Repartición de trípticos. Me permito informar para su superior conocimiento, se realiza el Operativo de prevención de hechos de tránsito entregando trípticos con las recomendaciones "USO OBLIGATORIO DEL CASCO Y RECOMENDACIONES DE SEGURIDAD VIAL" en las vías públicas. Sin novedad. USO DEL CASCO Personas concientizadas (32) A cargo: Marisol Hernández Vieyra Elementos de apoyo: Lázaro Bernal Marin Enoc Martínez Rogel Juan Alonso Jerónimo Unidad: 19-3978 Kilómetros: 6. Reporta el Encargado de la Delegación 10 Zitácuaro de la Coordinación del Agrupamiento de Seguridad Vial. Cmte. José María Mendoza Farías. | J18: CAMPAÑAS_Images/d09f8588.Foto 1-2.173037.jpg | K18: CAMPAÑAS_Images/d09f8588.Foto 2-2.173037.jpg | L18: 32 | M18: 4 | O18: 1 | P18: 0 | Q18: 6 | R18: 35 | S18: ZITACUARO | T18: CAMPAÑAS
A19: 90e5775d | B19: 90e5775d | C19: LAZARO CARDENAS - ARTEAGA | D19: CONCIENTIZACIÓN Y PREVENCIÓN | E19: 46129 | F19: 0.47912037 | G19: RESPETA LOS LIMITES DE VELOCIDAD | I19: *G U A R D I A C I V I L* *COORDINACION DEL AGRUPAMIENTO DE SEGURIDAD VIAL* *REGIÓN LÁZARO CÁRDENAS* *UNIDAD DE DELEGACIÓNES* *DELEGACIÓN 36 ARTEAGA* *VIERNES 17 DE ABRIL 2026* *Asunto:* *Campaña de Prevención de Accidentes.* 11:10 HORAS. Guardia civil "Seguridad Vial" informa que se continúa con la entrega de trípticos con la leyenda de **Recomendaciónes de Seguridad Vial**para la concientización y prevención de accidentes viales, en las principales calles, avenidas y tramos carreteros de este municipio. Reporta el Encargado de la Delegación 36 Arteaga C.Moises Zarco Cuevas de la Coordinación del Agrupamiento de Seguridad Vial | J19: CAMPAÑAS_Images/90e5775d.Foto 1-2.173119.jpg | K19: CAMPAÑAS_Images/90e5775d.Foto 2-2.173119.jpg | L19: 20 | M19: 2 | O19: 1 | P19: 0 | Q19: 15 | R19: 10 | S19: LAZARO CARDENAS | T19: CAMPAÑAS
A20: 0e5a22d5 | B20: 0e5a22d5 | C20: ZAMORA - ZAMORA | D20: CONCIENTIZACIÓN Y PREVENCIÓN | E20: 46129 | F20: 0.49508102 | G20: UTILIZA EL CINTURON DE SEGURIDAD | I20: GUARDIA CIVIL COORDINACION DEL AGRUPAMIENTO DE SEGURIDAD VIAL UNIDAD DE DELEGACIÓNES REGIÓN ZAMORA VIERNES 17 DE ABRIL DE 2026 ASUNTO: ENTREGA DE TRÍPTICOS 11: 15 horas Señor Coordinador, Señor Subdirector para su superior conocimiento me permito informar que continuamos dando cumplimiento a las órdenes superiores con la campaña de seguridad vial repartiendo trípticos a conductores de Vehiculos haciendo la recomendación del uso del Cinturón de seguridad prevenir accidentes o lesiones en las vías públicas. Pie tierra Elementos: 1.- Emiliano Manrriquez Velázquez 2 Juan Santos Toxtega Bustamante Reportó el encargado de la Delegación Cmte Alfredo Velázquez González. Coordinación del Agrupamiento De Seguridad Vial. | J20: CAMPAÑAS_Images/0e5a22d5.Foto 1-2.175439.jpg | K20: CAMPAÑAS_Images/0e5a22d5.Foto 2-2.175439.jpg | L20: 8 | M20: 2 | O20: 0 | P20: 0 | Q20: 1 | R20: 27 | S20: ZAMORA | T20: CAMPAÑAS
A21: 4275f84e | B21: 4275f84e | C21: ZITACUARO - ZITACUARO | D21: CONCIENTIZACIÓN Y PREVENCIÓN | E21: 46129 | F21: 0.49493056 | G21: RESPETA LOS LIMITES DE VELOCIDAD | I21: G U A R D I A C I V I L COORDINACIÓN DEL AGRUPAMIENTO DE SEGURIDAD VIAL UNIDAD DE DELEGACIONES REGIÓN ZITACUARO DELEGACIÓN 10 ZITÁCUARO MIÉRCOLES 17 DE ABRIL DEL 2026 ASUNTO: Recomendaciones a Conductores de "Servicio público" Por medio de la presente se informa que se les hace recomendaciones a los conductores de servicio público que conduzcan con responsabilidad, y a cumplir debidamente con su documentación y a pasajeros tomar medidas preventivas para evitar accidentes. Recomendaciones a pasajeros 1. Ir atentos a su recorrido. 2. Hacer uso de los números de emergencia (089 o 911) ante cualquier suceso. 3. Realizar ascenso y descenso en paradas establecidas. 4. Ir sentados correctamente Conductores de servicio público concientizados (27). Quedando pendientes y a la orden. A cargo Marisol Hernández Vieyra Elementos de apoyo: Lázaro Bernal Marín Enoc Martínez Rogel Juan Alonso Jerónimo *Unidad:*3180 Kilómetros: 8 Reporta el Encargado de la Delegación 10 Zitácuaro de la Coordinación del Agrupamiento de Seguridad Vial. Cmte. José María Mendoza Farías | J21: CAMPAÑAS_Images/4275f84e.Foto 1-2.175458.jpg | K21: CAMPAÑAS_Images/4275f84e.Foto 2-2.175458.jpg | L21: 27 | M21: 4 | O21: 1 | P21: 0 | Q21: 8 | R21: 35 | S21: ZITACUARO | T21: CAMPAÑAS
A22: cda523b0 | B22: cda523b0 | C22: LA PIEDAD - YURECUARO | D22: REPARTICIÓN DE TRÍPTICOS | E22: 46129 | F22: 0.50069444 | G22: RESPETA LOS LIMITES DE VELOCIDAD | I22: Guardia Civil Coordinación del agrupamiento de Seguridad Vial Unidad de delegaciones Delegación 21 Yurécuaro Fecha:. 17 de Abril del 2026 Hora: 11:00 hrs Asunto: Entrega de trípticos. Por medio de la presente me permito informar, se hace entrega de trípticos con la leyenda de Respeta los límites de velocidad esto con la finalidad de dar a conocer a la ciudadanía. Unidad 03-625 El Policía: Gustavo Saavedra Ramirez Informa el encargado de la delegación 21 Yurécuaro de seguridad vial Gustavo Saavedra Ramirez | J22: CAMPAÑAS_Images/cda523b0.Foto 1-2.180143.jpg | K22: CAMPAÑAS_Images/cda523b0.Foto 2-2.180143.jpg | L22: 10 | M22: 1 | O22: 1 | P22: 0 | Q22: 15 | R22: 6 | S22: LA PIEDAD | T22: CAMPAÑAS
A23: 532207ac | B23: 532207ac | C23: ZAMORA - ZAMORA | D23: CONCIENTIZACIÓN Y PREVENCIÓN | E23: 46129 | F23: 0.58478009 | G23: USO DE CASCO | I23: GUARDIA CIVIL COORDINACIÓN DEL AGRUPAMIENTO DE SEGURIDAD VIAL UNIDAD DE DELEGACIONES REGION ZAMORA VIERNES 17 DE ABRIL DEL 2026 14:00 HORAS Asunto: Motociclista Responsable uso del casco Guardia Civil "Seguridad Vial Estatal" informa que se continúa con la Campaña de las Consecuencias de No usar el Casco de Seguridad (en una Motocicleta), como puede ser la Gravedad de la Lesiones, Posibilidades de Muerte y a tiempo de Hospitalización .,los cuales se le hace concientización de lo hechos de Conducir Un Vehículo Birodante , por lo que se da de Conocimiento a la Superioridad de lo elaborado hacia la Ciudadanía por lo que al momento se encuentra sin Ninguna Novedad. Informa C. Emiliano manrriquez Velázquez con 01 más pie tierra Reporta el Encargado de la Delegación C. Alfredo Velázquez González de la Coordinación del Agrupamiento de Seguridad Vial. | J23: CAMPAÑAS_Images/532207ac.Foto 1-2.200344.jpg | K23: CAMPAÑAS_Images/532207ac.Foto 2-2.200344.jpg | L23: 8 | M23: 2 | O23: 0 | P23: 0 | Q23: 1 | R23: 27 | S23: ZAMORA | T23: CAMPAÑAS
A24: a60cdd1c | B24: a60cdd1c | C24: LA PIEDAD - LA PIEDAD | D24: CONCIENTIZACIÓN Y PREVENCIÓN | E24: 46129 | F24: 0.59512731 | G24: UTILIZA EL CINTURON DE SEGURIDAD | I24: GUARDIA CIVIL* *COORDINACIÓN DEL AGRUPAMIENTO DE SEGURIDAD VIAL* *UNIDAD DE DELEGACIÓNES* *REGION LA PIEDAD* *DELEGACIÓN LA PIEDAD* *VIERNES 17 DE ABRIL DE 2026* *14:30 HORAS* *ASUNTO:* Campaña prevención y concientización Por medio de la presente me permito informar que se da cumplimiento a las órdenes giradas por la superioridad, se realiza proximidad social, realizando entrega de trípticos con la leyenda *Utiliza cinturón de Seguridad* esto con la finalidad de crear conciencia y dar a conocer un poco las obligaciones q tenemos como conductores. Informa la Unidad 3405 a cargo del Pol. Arturo Buenrostro Rodríguez de la Delegación de Seguridad Vial de La Piedad. Reporta el encargado de la Delegación Pol. 2° J. Jesús Arévalo León de la coordinación del Agrupamiento de Seguridad Vial. | J24: CAMPAÑAS_Images/a60cdd1c.Foto 1-2.203245.jpg | K24: CAMPAÑAS_Images/a60cdd1c.Foto 2-2.203245.jpg | L24: 21 | M24: 3 | O24: 1 | P24: 0 | Q24: 8 | R24: 4 | S24: LA PIEDAD | T24: CAMPAÑAS
A25: b9747e9b | B25: b9747e9b | C25: ZAMORA - TANGANCICUARO | D25: TALLER EDUCACIÓN SEGURIDAD VIAL | E25: 46129 | F25: 0.7037037 | I25: *GUARDIA CIVIL* *COORDINACIÓN DEL AGRUPAMIENTO DE SEGURIDAD VIAL* *UNIDAD DE DELEGACIONES* *REGION ZAMORA* *DELEGACIÓN 23 TANGANCÍCUARO.* .VIERNES 17 DE ABRIL DEL 2026.* *HORA:* 15:30 *ASUNTO*: Plática de manejo a la defensiva de Seguridad Vial. Se informa para su superior conocimiento que se realiza una platica de *_Manejo a la Defensiva y educación vial_*, virtual y presencial a personal de la empresa del grupo Agricola el Cerezo, ubicada en Prolongación Jesús González Ortega, colonia Sector 1, en el municipio de tangancicuaro de arista Michoacán, con un aproximado de 50 personas, impartida por personal operativo y administrativo de esta delegación bajo mi cargo. Informan los agentes de seguridad víal: Isauro Hernández Noyola Jorge Alejandro González Melgarejo. *REPORTA* Encargado de la coordinación del agrupamiento de seguridad vial. *Cmte. Isauro Hernández Noyola.* | J25: CAPACITACIONES_Images/b9747e9b.Foto 1-2.225207.jpg | K25: CAPACITACIONES_Images/b9747e9b.Foto 2-2.225207.jpg | L25: 50 | M25: 2 | O25: 1 | P25: 0 | Q25: 2 | R25: 34 | S25: ZAMORA | T25: CAPACITACIONES
A26: deb83033 | B26: deb83033 | C26: HUETAMO - HUETAMO | D26: PASOS PEATONALES | E26: 46128 | F26: 0.70900463 | I26: *Guardia Civil * *Coordinación del Agrupamiento de Seguridad Vial* *Unidad de Delegaciones* *Región Huetamo* *Delegación 12 Huetamo* Jueves 16 de Abril del 2026* *Asunto:* Apoyo en el Paso peatonal en la zona centro. *17:00 Horas* Por medio de la presente se informa al mando que se realiza el apoyo del paso peatonal y la seguridad en zona centro con la finalidad de salvaguardar la integridad física de la ciudadanía y así evitar accidentes. Al momento todo sin novedad de relevancia continuamos pendientes y a la orden. Estado de Fuerza; PIE TIERRA 👮🏻‍♂️ Julián González Pineda. Informa el Oficial Julián González Pineda elemento de la Delegación Regional 12 de Seguridad Vial. Reportó Cmdte. Florencio Reynoso Gómez, Encargado de la Delegación regional 12 de Seguridad Vial. | J26: DISPOSITIVOS DE SEGURIDAD VIAL_Images/deb83033.Foto 1-2.231622.jpg | K26: DISPOSITIVOS DE SEGURIDAD VIAL_Images/deb83033.Foto 2-2.231622.jpg | L26: 4 | M26: 1 | O26: 0 | P26: 0 | Q26: 0 | R26: 16 | S26: HUETAMO | T26: DISPOSITIVOS DE SEGURIDAD VIAL
A27: 76ceda15 | B27: 76ceda15 | C27: LAZARO CARDENAS - LAZARO CARDENAS | D27: PASOS PEATONALES | E27: 46128 | F27: 0.73015046 | I27: G U A R D I A C I V I L COORDINACIÓN DEL AGRUPAMIENTO DE SEGURIDAD VIAL UNIDAD DE DELEGACIONES REGIÓN LAZARO CARDENAS DELEGACIÓN 17 LAZARO CÁRDENAS Jueves 16 de Abril del 2026 17:10 horas Asunto: Apoyo a peatones Por medio de la presente me permito informar a usted que con esta hora se brinda apoyo a peatones para prevenir hechos de tránsito en la avenidad LázaroCárdenas. Reporta el encargado de la Delegación Lazaro Cárdenas de la coordinación del Agrupamiento de Seguridad Vial Oficial Victor Omar Sedano Gómez | J27: DISPOSITIVOS DE SEGURIDAD VIAL_Images/76ceda15.Foto 1-2.233641.jpg | K27: DISPOSITIVOS DE SEGURIDAD VIAL_Images/76ceda15.Foto 2-2.233641.jpg | L27: 50 | M27: 1 | O27: 1 | P27: 0 | Q27: 1 | R27: 9 | S27: LAZARO CARDENAS | T27: DISPOSITIVOS DE SEGURIDAD VIAL
A28: 0f084060 | B28: 0f084060 | C28: COALCOMAN - COALCOMAN | D28: PATRULLAJES | E28: 46128 | F28: 0.74483796 | I28: *Guardia Civil* *Unidad Dé Delegaciones* *Región Coalcoman* *Delegación 030 Coalcoman* *Jueves 16 de abril del 2026.* 16:40 horas. *Asunto:* Carretera segura. Por medio de la presente me permito informar a mi superioridad, que el personal de está delegación de seguridad vial, nos encontramos realizando recorridos intinerantes de vigilancia sobre la carretera estatal Coalcoman-Tepalcatepec ( localidad piedras de lumbre), con la finalidad de evitar algún hecho delictivo, auxiliar a conductores en caso de falla mecánica y crear la confianza entre la sociedad *Elementos participantes* 1-.Leonardo Rolón Meraz.(Responsable) 2.- Sergio Suárez Jiménez. *Abordo de la unidad oficial 03-608* 24 - kilómetros. Terminando el recorrido.alas 17:50 horas, sin novedad. Lo que me permito informar Respetuosamente. Integrante de la coordinación de Seguridad Vial Estatal delegación 030 región Coalcoman Cmte. Leonardo Rolón Meraz. | J28: DISPOSITIVOS DE SEGURIDAD VIAL_Images/0f084060.Foto 1-2.235349.jpg | K28: DISPOSITIVOS DE SEGURIDAD VIAL_Images/0f084060.Foto 2-2.235349.jpg | L28: 0 | M28: 2 | O28: 1 | P28: 0 | Q28: 24 | R28: 11 | S28: COALCOMAN | T28: DISPOSITIVOS DE SEGURIDAD VIAL
A29: 3041aa5b | B29: 3041aa5b | C29: MORELIA - ZINAPECUARO | D29: PATRULLAJES | E29: 46128 | F29: 0.7902662 | I29: *G U A R D I A C I V I L* *COORDINACIÓN DEL AGRUPAMIENTO DE SEGURIDAD VIAL* *UNIDAD DE DELEGACIONES* *REGIÓN MORELIA* *DELEGACIÓN 016 ZINAPECUARO* *16/04/2026* *18:50 HORAS* *Asunto: Monitoreo de la autopista* *Ubicación:*Autopista de Occidente Méx-GDL Km 202+256, Plaza de Cobro de Zinapecuaro* *CRP 04374* 🟢 *LIBRE* (Circulación Libre Guardia Civil Seguridad Vial Zinapecuaro para conocimiento de la superioridad se informa que Continua fluyendo la circulación en ambos sentidos la caseta de peaje México Guadalajara y Guadalajara México hasta el momento sin novedad reportado sin novedad | J29: DISPOSITIVOS DE SEGURIDAD VIAL_Images/3041aa5b.Foto 1-2.005848.jpg | K29: DISPOSITIVOS DE SEGURIDAD VIAL_Images/3041aa5b.Foto 2-2.005848.jpg | L29: 0 | M29: 3 | O29: 1 | P29: 0 | Q29: 18 | R29: 20 | S29: MORELIA | T29: DISPOSITIVOS DE SEGURIDAD VIAL
A30: 2ca95bb1 | B30: 2ca95bb1 | C30: ZAMORA - ZAMORA | D30: PASOS PEATONALES | E30: 46128 | F30: 0.80765046 | I30: GUARDIA CIVIL COORDINACION DEL AGRUPAMIENTO DE SEGURIDAD VIAL UNIDAD DE DELEGACIÓNES REGION ZAMORA JUEVES 16 DE ABRIL DE 2026 ASUNTO: CRUCES PEATONALES 18 : 00 Horas Por medio del presente se informa. Que se realizan apoyos en cruces peatonales dando seguridad a las personas, deteniendo el paso vehicular y dando información a la ciudadanía, de la forma correcta en la que tienen que cruzar y ubicar estás zonas Peatonales para una mejor aplicación y cruce. Sin novedad hasta el momento Informa Policía de Seguridad Vial Emiliano Manriquez Velázquez con uno más, Pie tierra. Reportó el encargado de la Delegación Cmte: Alfredo Velázquez González. Coordinación del Agrupamiento de Seguridad Vial | J30: DISPOSITIVOS DE SEGURIDAD VIAL_Images/2ca95bb1.Foto 1-2.012355.jpg | K30: DISPOSITIVOS DE SEGURIDAD VIAL_Images/2ca95bb1.Foto 2-2.012355.jpg | L30: 0 | M30: 2 | O30: 0 | P30: 0 | Q30: 1 | R30: 27 | S30: ZAMORA | T30: DISPOSITIVOS DE SEGURIDAD VIAL
A31: 8c095784 | B31: 8c095784 | C31: APATZINGAN - GABRIEL ZAMORA | D31: PATRULLAJES | E31: 46128 | F31: 0.81377315 | I31: *GUARDIA CIVIL* *COORDINACIÓN DEL AGRUPAMIENTO DE SEGURIDAD VIAL* *UNIDAD DE DELEGACIONES* *REGIÓN APATZINGÁN* *DELEGACION GABRIEL ZAMORA* *ASUNTO: CARRETERAS SEGURAS* *FECHA: 16/04/2026* *HORA: 17:30 HRS* Por medio de la presente me permito informar a usted que continua los patrullajes en el marco de Carreteras seguras realizando recorridos de prevención, vigilancia y disuasión del delito implementado por la coordinación del agrupamiento de seguridad vial para auxiliar y resguardar la integridad a las familias , hasta el momento sin novedad. Ubicación Km 122 Carretera Federal libre Carapan- Playa azul UNIDAD : 3138 Julio Cesar Silva Mendoza *INFORMA* *JULIO CESAR SILVA MENDOZA, ENCARGADO DE LA DELEGACIÓN GABRIEL ZAMORA.* | J31: DISPOSITIVOS DE SEGURIDAD VIAL_Images/8c095784.Foto 1-2.013309.jpg | K31: DISPOSITIVOS DE SEGURIDAD VIAL_Images/8c095784.Foto 2-2.013309.jpg | L31: 0 | M31: 1 | O31: 1 | P31: 0 | Q31: 24 | R31: 15 | S31: APATZINGAN | T31: DISPOSITIVOS DE SEGURIDAD VIAL
A32: 9169fd00 | B32: 9169fd00 | C32: ZITACUARO - ZITACUARO | D32: PATRULLAJES | E32: 46128 | F32: 0.82685185 | I32: G U A R D I A C I V I L COORDINACIÓN DEL AGRUPAMIENTO DE SEGURIDAD VIAL UNIDAD DE DELEGACIONES REGIÓN ZITACUARO DELEGACIÓN 10 ZITÁCUARO JUEVES 16 DE ABRIL DEL 2026 Asunto: Recorrido de la Carretera Segura. Por medio de la presente Me permito informar que se continua con los Recorridos de patrullaje y vigilancia sobre las Carreteras Estatales y Vias Publicas; haciendo presencia y proporcionando Seguridad a la ciudadanía. El cual se lleva a cabo dentro del municipio de Zitácuaro Michoacán. CARRETERA (ZITACUARO-TOLUCA Y ZITÁCUARO-MORELIA) SIN NOVEDAD A cargo: Diana Marin Colin Elementos de apoyo: Lázaro Bernal Marin Marisol Hernández Vieyra Juan Alonso Jerónimo Enoc Martínez Rogel Unidad: 193978 Kilómetros: 20 Es lo que me permito a usted informar para su superior conocimiento quedando sin novedad. Reporta el encargado de la Delegación 10 Zitácuaro de la coordinación del Agrupamiento de Seguridad Vial. Cmte. José María Mendoza Farías. | J32: DISPOSITIVOS DE SEGURIDAD VIAL_Images/9169fd00.Foto 1-2.015135.jpg | K32: DISPOSITIVOS DE SEGURIDAD VIAL_Images/9169fd00.Foto 2-2.015135.jpg | L32: 0 | M32: 5 | O32: 1 | P32: 0 | Q32: 20 | R32: 35 | S32: ZITACUARO | T32: DISPOSITIVOS DE SEGURIDAD VIAL
A33: d3ddac70 | B33: d3ddac70 | C33: LAZARO CARDENAS - ARTEAGA | D33: PATRULLAJES | E33: 46128 | F33: 0.83633102 | I33: *G U A R D I A C I V I L* *COORDINACION DE AGRUPAMIENTO DE SEGURIDAD VIAL* *REGIÓN LÁZARO CÁRDENAS* *UNIDAD DE DELEGACIÓNES* *DELEGACIÓN 36 ARTEAGA* *JUEVES 16 DE ABRIL 2026* *20:00 hrs.* *Asunto*. Recorridos de Prevencion por medio del presente se informa a la superioridad que al momento se realizan recorridos de prevención y disuasión del delito por las diferentes carreteras, calles y avenidas de esta cabecera Municipal en la unidad 04-153 Sin novedad relevante. Reportó el Encargado de la Delegación 36 Arteaga C.Moises Zarco Cuevas de la Coordinación del Agrupamiento de seguridad vial | J33: DISPOSITIVOS DE SEGURIDAD VIAL_Images/d3ddac70.Foto 1-2.020743.jpg | K33: DISPOSITIVOS DE SEGURIDAD VIAL_Images/d3ddac70.Foto 2-2.020743.jpg | L33: 0 | M33: 1 | O33: 1 | P33: 0 | Q33: 2 | R33: 10 | S33: LAZARO CARDENAS | T33: DISPOSITIVOS DE SEGURIDAD VIAL
A34: b7f23275 | B34: b7f23275 | C34: ZAMORA - COENEO | D34: PATRULLAJES | E34: 46128 | F34: 0.84810185 | I34: *GUARDÍA CIVIL* *COORDINACIÓN DEL AGRUPAMIENTO DE SEGURIDAD VÍAL* *UNIDAD DE DELEGACIÓNES* *REGIÓN ZAMORA* *DELEGACIÓN 41 COENEO* *JUEVES 16 DE ABRIL DE 2026* *19:10 HORAS* *UBICACIÓN; COMANJA-HUANIQUEO* *ASUNTO: PATRULLAJES DE PREVENCIÓN* Por medio de la Presente se informa a la Superioridad que se realizan recorridos sobre las carreteras pertenecientes a esta encontrándose al momento sin novedad. *Informa la unidad 03-621* *Personas alcanzadas 50* *Km recorridos 10* *Reporta Encargado de La Delegación de Seguridad vial de Coeneo; Clemente Vázquez Ávalos.* | J34: DISPOSITIVOS DE SEGURIDAD VIAL_Images/b7f23275.Foto 1-2.022229.jpg | K34: DISPOSITIVOS DE SEGURIDAD VIAL_Images/b7f23275.Foto 2-2.022229.jpg | L34: 50 | M34: 2 | O34: 1 | P34: 0 | Q34: 10 | R34: 30 | S34: ZAMORA | T34: DISPOSITIVOS DE SEGURIDAD VIAL
A35: d5899086 | B35: d5899086 | C35: LA PIEDAD - LA PIEDAD | D35: PASOS PEATONALES | E35: 46128 | F35: 0.85770833 | I35: *GUARDIA CIVIL* *COORDINACIÓN DEL AGRUPAMIENTO DE SEGURIDAD VIAL* *UNIDAD DE DELEGACIÓNES* *REGION LA PIEDAD* *DELEGACIÓN LA PIEDAD* *JUEVES16 DE ABRIL DE 2026* *20:10 HORAS* *ASUNTO:* Cruces Peatonales Para conocimiento del Mando, me permito informar que se está implementando un programa de concientización a la ciudadanía sobre el cruce y seguridad peatonal, invitándolos a cruzar por las rayas peatonales o lugares señalados y marcados en las esquinas. Informa la Unidad 3405 a cargo del Pol. Arturo Buenrostro Rodríguez de la Delegación de Seguridad Vial de La Piedad. Reporta el encargado de la Delegación Pol. 2° J. Jesús Arévalo León de la coordinación del Agrupamiento de Seguridad Vial. | J35: DISPOSITIVOS DE SEGURIDAD VIAL_Images/d5899086.Foto 1-2.023638.jpg | K35: DISPOSITIVOS DE SEGURIDAD VIAL_Images/d5899086.Foto 2-2.023638.jpg | L35: 0 | M35: 2 | O35: 1 | P35: 0 | Q35: 6 | R35: 4 | S35: LA PIEDAD | T35: DISPOSITIVOS DE SEGURIDAD VIAL
A36: 4442e0a4 | B36: 4442e0a4 | C36: LA PIEDAD - VISTA HERMOSA | D36: PATRULLAJES | E36: 46128 | F36: 0.93482639 | I36: *Guardia Civil* *Coordinación Agrupamiento de Seguridad Vial* *Unidad de Delegaciones* *Región la Piedad* *Delegación 54 Vista Hermosa* *Jueves 16 De Abril 2026* *18:00 horas* *Asunto* Patrullajes en carreteras vecinales la Angostura y Capulin comunidades de Vista Hermosa. Para conocimiento de la Superioridad, me permito informar que se efectuaron patrullajes y vigilancia en tramos carreteros vecinales de las comunidades de este municipio de Vista Hermosa. Quedando al momento sin novedad de relevancia. *NOTA* Patrullaje Se Realiza Con La Unidad 019-79 de Tránsito Municipal A cargo de la Cmnte Denise Morales Con 1 Elemento Mas de Seguridad Vial. Reporta la encargada de la Delegación 54 Vista Hermosa de la Coordinacion del Agrupamiento de Seguridad Vial. Cmndte: Denise Azucena Morales Briseño | J36: DISPOSITIVOS DE SEGURIDAD VIAL_Images/4442e0a4.Foto 1-2.042652.jpg | K36: DISPOSITIVOS DE SEGURIDAD VIAL_Images/4442e0a4.Foto 2-2.042652.jpg | L36: 10 | M36: 2 | O36: 0 | P36: 0 | Q36: 10 | R36: 5 | S36: LA PIEDAD | T36: DISPOSITIVOS DE SEGURIDAD VIAL
... A51: 0d4e1724 | B51: 0d4e1724 | C51: MORELIA - SANTA CLARA | D51: APOYO A LA VIALIDAD | E51: 46129 | F51: 0.42840278 | I51: *G U A R D I A C I V I L* *COORDINACIÓN DEL AGRUPAMIENTO DE SEGURIDAD VIAL* *UNIDAD DE DELEGACIONES* *REGIÓN MORELIA* *DELEGACIÓN 45 SANTA CLARA DEL COBRE* *VIERNES 17 DE ABRIL DE 2026* *09:48 HORAS* *Asunto: Cortejo Fúnebre* Por medio de la presente se informa a la superioridad, que se presta el apoyo a un cortejo fúnebre realizando un corte de circulación en la avenida Morelos bajando por Ignacio Allende dando vuelta por la avenida Hidalgo hasta llegar al templo De la Inmaculada Concepción Personas alcanzadas: 100 Informan Elementos De Seguridad Vial: 1.- Raziel Contreras Viramontes 2.- Leopoldo Pérez Correa Reporta el encargado de la Delegación 45 de Santa Clara del Cobre, el *Sub. Oficial Calixto Vazquez Chávez* de la coordinación del Agrupamiento de Seguridad Vial | J51: DISPOSITIVOS DE SEGURIDAD VIAL_Images/0d4e1724.Foto 1-2.165720.jpg | K51: DISPOSITIVOS DE SEGURIDAD VIAL_Images/0d4e1724.Foto 2-2.165720.jpg | L51: 100 | M51: 2 | O51: 0 | P51: 0 | Q51: 0 | R51: 25 | S51: MORELIA | T51: DISPOSITIVOS DE SEGURIDAD VIAL
A52: 67659004 | B52: 67659004 | C52: LA PIEDAD - LA PIEDAD | D52: PASOS PEATONALES | E52: 46129 | F52: 0.45905093 | I52: GUARDIA CIVIL* *COORDINACIÓN DEL AGRUPAMIENTO DE SEGURIDAD VIAL* *UNIDAD DE DELEGACIÓNES* *REGION LA PIEDAD* *DELEGACIÓN LA PIEDAD* *VIERNES 17 DE ABRIL DE 2026* *10:10 HORAS* *ASUNTO:* Cruces Peatonales Para conocimiento del Mando, me permito informar que se está implementando un programa de concientización a la ciudadanía sobre el cruce y seguridad peatonal, invitándolos a cruzar por las rayas peatonales o lugares señalados y marcados en las esquinas. Informa la Unidad 3405 a cargo del Pol. Arturo Buenrostro Rodríguez de la Delegación de Seguridad Vial de La Piedad. Reporta el encargado de la Delegación Pol. 2° J. Jesús Arévalo León de la coordinación del Agrupamiento de Seguridad Vial. | J52: DISPOSITIVOS DE SEGURIDAD VIAL_Images/67659004.Foto 1-2.170126.jpg | K52: DISPOSITIVOS DE SEGURIDAD VIAL_Images/67659004.Foto 2-2.170126.jpg | L52: 0 | M52: 3 | O52: 1 | P52: 0 | Q52: 6 | R52: 4 | S52: LA PIEDAD | T52: DISPOSITIVOS DE SEGURIDAD VIAL
A53: 6f0f2073 | B53: 6f0f2073 | C53: MORELIA - PATZCUARO | D53: PATRULLAJES | E53: 46129 | F53: 0.46060185 | I53: *G U A R D I A C I V I L* *COORDINACIÓN DEL AGRUPAMIENTO DE SEGURIDAD VIAL* *UNIDAD DE DELEGACIONES* *REGIÓN MORELIA* *DELEGACION 01 DE PATZCUARO* *VIERNES 17 ABRIL DE 20226* *10:55 HORAS* *Asunto:* Recorrido de Supervisión y Seguridad Vial Por medio de la presente se informa a usted que se realizan recorridos continuos de supervisión y seguridad vial en zona centro de esta ciudad, Retirando vehículos mal estacionados, Activando circulación y prestando apoyo a paso de peatones los compañeros Pie-Tierra Pendientes en su lugar de servicio Se anexa material fotográfico. *Reporta el encargado de la Delegación Angel Peralta Hernández de la coordinación del Agrupamiento de Seguridad Vial* | J53: DISPOSITIVOS DE SEGURIDAD VIAL_Images/6f0f2073.Foto 1-2.170348.jpg | K53: DISPOSITIVOS DE SEGURIDAD VIAL_Images/6f0f2073.Foto 2-2.170348.jpg | L53: 600 | M53: 1 | O53: 1 | P53: 0 | Q53: 5 | R53: 19 | S53: MORELIA | T53: DISPOSITIVOS DE SEGURIDAD VIAL
A54: 5b3d0532 | B54: 5b3d0532 | C54: APATZINGAN - APATZINGAN | D54: PATRULLAJES | E54: 46129 | F54: 0.47123843 | I54: *G U A R D I A C I V I L .* *COORDINACIÓN DEL AGRUPAMIENTO DE SEGURIDAD VIAL .* *UNIDAD DE DELEGACIONES*. *REGIÓN APATZINGÁN* *DELEGACIÓN 07 APATZINGÁN* *VIERNES 17 DE ABRIL DEL 2026* *Asunto:* Recorridos de Prevención y proximidad social *11:09 HORAS* Para conocimiento de la superioridad, Se informa que está delegación de seguridad vial, realiza recorridos de prevención y Monitoreo sobre la carretera Apatzingán-Aguililla así como proximidad social en el centro recreativo Bioparque, ubicado sobre la misma carretera en el km. 4+500, hasta el momento sin novedad alguna. *Delegación de Seguridad Vial* 01.- Policía Adrián Alejandro Valle Vázquez 02.- Angel David Alejandre Tejeda Unidad: 04-157 Reporta el encargado de la delegación Apatzingán de la coordinación del Agrupamiento de Seguridad vial. Cmte. Julio Duvalier Hernández de la Cruz. | J54: DISPOSITIVOS DE SEGURIDAD VIAL_Images/5b3d0532.Foto 1-2.171914.jpg | K54: DISPOSITIVOS DE SEGURIDAD VIAL_Images/5b3d0532.Foto 2-2.171914.jpg | L54: 0 | M54: 2 | O54: 1 | P54: 0 | Q54: 10 | R54: 13 | S54: APATZINGAN | T54: DISPOSITIVOS DE SEGURIDAD VIAL
...

Sheet ALERTA #
A3: No. | B3: CATEGORÍA | C3: ACTIVIDAD | D3: MORELIA | G3: JIQUILPAN | J3: ZAMORA | M3: LA PIEDAD | P3: URUAPAN | S3: APATZINGAN | V3: HUETAMO | Y3: COALCOMAN | AB3: ZITACUARO | AE3: LAZARO CARDENAS
A4: 1 | B4: INSTITUCIONES | C4: APOYO A EVENTOS PÚBLICOS | D4: 0 | E4: 0 | G4: 0 | H4: 0 | J4: 0 | K4: 0 | M4: 0 | N4: 0 | P4: 0 | Q4: 0 | S4: 0 | T4: 0 | V4: 0 | W4: 0 | Y4: 0 | Z4: 0 | AB4: 0 | AC4: 0 | AE4: 0 | AF4: 0
C5: APOYO A EVENTOS DEPORTIVOS | D5: 0 | E5: 0 | G5: 0 | H5: 0 | J5: 0 | K5: 0 | M5: 0 | N5: 0 | P5: 0 | Q5: 0 | S5: 0 | T5: 0 | V5: 0 | W5: 0 | Y5: 0 | Z5: 0 | AB5: 0 | AC5: 0 | AE5: 0 | AF5: 0
C6: APOYO A EVENTOS CULTURALES | D6: 0 | E6: 0 | G6: 0 | H6: 0 | J6: 0 | K6: 0 | M6: 0 | N6: 0 | P6: 0 | Q6: 0 | S6: 0 | T6: 0 | V6: 0 | W6: 0 | Y6: 0 | Z6: 0 | AB6: 0 | AC6: 0 | AE6: 0 | AF6: 0
C7: APOYO A EVENTOS RELIGIOSOS | D7: 0 | E7: 0 | G7: 0 | H7: 0 | J7: 0 | K7: 0 | M7: 0 | N7: 0 | P7: 0 | Q7: 0 | S7: 0 | T7: 0 | V7: 0 | W7: 0 | Y7: 0 | Z7: 0 | AB7: 0 | AC7: 1 | AE7: 0 | AF7: 0
C8: APOYOS A OTRAS DEPENDENCIAS (Publicas o privadas) | D8: 5 | E8: 5 | G8: 0 | H8: 0 | J8: 1 | K8: 1 | M8: 0 | N8: 0 | P8: 0 | Q8: 0 | S8: 0 | T8: 0 | V8: 0 | W8: 0 | Y8: 0 | Z8: 0 | AB8: 0 | AC8: 0 | AE8: 0 | AF8: 0
C9: ESCUELAS | D9: 8 | E9: 17 | G9: 5 | H9: 5 | J9: 7 | K9: 11 | M9: 8 | N9: 8 | P9: 7 | Q9: 7 | S9: 4 | T9: 4 | V9: 1 | W9: 4 | Y9: 0 | Z9: 2 | AB9: 15 | AC9: 17 | AE9: 3 | AF9: -10
C10: DILIGENCIAS | D10: 1 | E10: 1 | G10: 0 | H10: 0 | J10: 0 | K10: 0 | M10: 0 | N10: 0 | P10: 0 | Q10: 0 | S10: 0 | T10: 0 | V10: 0 | W10: 0 | Y10: 0 | Z10: 0 | AB10: 0 | AC10: 0 | AE10: 0 | AF10: 0
C11: OTROS TIPOS (Especificar en las novedades relevantes) | D11: 0 | E11: 0 | G11: 0 | H11: 0 | J11: 0 | K11: 0 | M11: 0 | N11: 0 | P11: 0 | Q11: 0 | S11: 0 | T11: 0 | V11: 0 | W11: 0 | Y11: 0 | Z11: 0 | AB11: 0 | AC11: 0 | AE11: 0 | AF11: 0
A12: 2 | B12: REPORTES C5i | C12: OBSTRUCCIÓN DE COCHERAS | D12: 0 | E12: 0 | G12: 0 | H12: 0 | J12: 0 | K12: 0 | M12: 0 | N12: 0 | P12: 0 | Q12: 0 | S12: 0 | T12: 0 | V12: 0 | W12: 0 | Y12: 0 | Z12: 0 | AB12: 0 | AC12: 0 | AE12: 0 | AF12: 0
C13: OTROS TIPOS DE OBSTRUCCIÓN | D13: 0 | E13: 0 | G13: 0 | H13: 0 | J13: 0 | K13: 0 | M13: 0 | N13: 0 | P13: 0 | Q13: 0 | S13: 0 | T13: 0 | V13: 0 | W13: 0 | Y13: 0 | Z13: 0 | AB13: 0 | AC13: 0 | AE13: 0 | AF13: 0
C14: ACTOS DELICTIVOS | D14: 0 | E14: 0 | G14: 0 | H14: 0 | J14: 0 | K14: 0 | M14: 0 | N14: 0 | P14: 0 | Q14: 0 | S14: 0 | T14: 0 | V14: 0 | W14: 0 | Y14: 0 | Z14: 0 | AB14: 0 | AC14: 0 | AE14: 0 | AF14: 0
C15: SINIESTROS | D15: 0 | E15: 0 | G15: 0 | H15: 0 | J15: 2 | K15: 2 | M15: 0 | N15: 0 | P15: 1 | Q15: 1 | S15: 0 | T15: 0 | V15: 0 | W15: 0 | Y15: 0 | Z15: 0 | AB15: 0 | AC15: 0 | AE15: 0 | AF15: 0
C16: HECHOS DE TRÁNSITO | D16: 1 | E16: 1 | G16: 0 | H16: 0 | J16: 1 | K16: 1 | M16: 0 | N16: 0 | P16: 0 | Q16: 0 | S16: 0 | T16: 0 | V16: 2 | W16: 2 | Y16: 0 | Z16: 0 | AB16: 1 | AC16: 1 | AE16: 0 | AF16: 0
C17: CONSENTRACION PERSONAS | D17: 0 | E17: 0 | G17: 0 | H17: 0 | J17: 0 | K17: 0 | M17: 0 | N17: 0 | P17: 0 | Q17: 0 | S17: 0 | T17: 0 | V17: 0 | W17: 0 | Y17: 0 | Z17: 0 | AB17: 0 | AC17: 0 | AE17: 0 | AF17: 0
C18: OTROS REPORTES (Especificar en las novedades relevantes) | D18: 0 | E18: 0 | G18: 0 | H18: 0 | J18: 0 | K18: 0 | M18: 0 | N18: 0 | P18: 0 | Q18: 0 | S18: 0 | T18: 0 | V18: 0 | W18: 0 | Y18: 0 | Z18: 0 | AB18: 0 | AC18: 0 | AE18: 0 | AF18: 0
A19: 3 | B19: ABANDERAMIENTOS | C19: CORTES DE CIRCULACIÓN | D19: 7 | E19: 7 | G19: 0 | H19: 0 | J19: 0 | K19: 0 | M19: 0 | N19: 0 | P19: 0 | Q19: 0 | S19: 0 | T19: 0 | V19: 1 | W19: 1 | Y19: 0 | Z19: 0 | AB19: 3 | AC19: 3 | AE19: 0 | AF19: 0
C20: ACCIDENTES | D20: 0 | E20: 0 | G20: 0 | H20: 0 | J20: 0 | K20: 1 | M20: 0 | N20: 0 | P20: 0 | Q20: 0 | S20: 0 | T20: 0 | V20: 0 | W20: 0 | Y20: 0 | Z20: 0 | AB20: 0 | AC20: 0 | AE20: 0 | AF20: 0
C21: MARCHAS | D21: 0 | E21: 0 | G21: 0 | H21: 0 | J21: 0 | K21: 0 | M21: 0 | N21: 0 | P21: 0 | Q21: 0 | S21: 0 | T21: 0 | V21: 0 | W21: 0 | Y21: 0 | Z21: 0 | AB21: 0 | AC21: 0 | AE21: 0 | AF21: 0
C22: MÍTINES | D22: 0 | E22: 0 | G22: 0 | H22: 0 | J22: 0 | K22: 0 | M22: 0 | N22: 0 | P22: 0 | Q22: 0 | S22: 0 | T22: 0 | V22: 0 | W22: 0 | Y22: 0 | Z22: 0 | AB22: 0 | AC22: 0 | AE22: 0 | AF22: 0
C23: OBRAS PÚBLICAS | D23: 0 | E23: 0 | G23: 0 | H23: 0 | J23: 0 | K23: 0 | M23: 0 | N23: 0 | P23: 0 | Q23: 0 | S23: 0 | T23: 0 | V23: 0 | W23: 0 | Y23: 0 | Z23: 0 | AB23: 2 | AC23: 2 | AE23: 0 | AF23: 0
C24: ACOMPAÑAMIENTO A CARAVANAS U OTROS | D24: 0 | E24: 0 | G24: 0 | H24: 0 | J24: 0 | K24: 0 | M24: 1 | N24: 1 | P24: 0 | Q24: 0 | S24: 0 | T24: 0 | V24: 0 | W24: 0 | Y24: 0 | Z24: 0 | AB24: 0 | AC24: 0 | AE24: 0 | AF24: 0
C25: OTROS ABANDERAMIENTOS (Especificar en las novedades relevantes) | D25: 0 | E25: 0 | G25: 0 | H25: 0 | J25: 0 | K25: 0 | M25: 0 | N25: 0 | P25: 0 | Q25: 0 | S25: 0 | T25: 0 | V25: 0 | W25: 0 | Y25: 0 | Z25: 0 | AB25: 0 | AC25: 0 | AE25: 0 | AF25: 0
A26: 4 | B26: OPERATIVOS | C26: ESCUELAS SEGURAS | D26: 21 | E26: 17 | G26: 8 | H26: 5 | J26: 17 | K26: 11 | M26: 13 | N26: 13 | P26: 13 | Q26: 7 | S26: 9 | T26: 4 | V26: 4 | W26: 4 | Y26: 4 | Z26: 2 | AB26: 24 | AC26: 17 | AE26: 9 | AF26: -10
C27: GUARDIAN VIAL | D27: 17 | E27: 11 | G27: 0 | H27: 0 | J27: 20 | K27: 15 | M27: 0 | N27: 0 | P27: 1 | Q27: 0 | S27: 0 | T27: 0 | V27: 0 | W27: 0 | Y27: 0 | Z27: 0 | AB27: 18 | AC27: 12 | AE27: 0 | AF27: 0
C28: MONITOREO INTEGRAL | D28: 7 | E28: 5 | G28: 0 | H28: 0 | J28: 19 | K28: 14 | M28: 0 | N28: 0 | P28: 5 | Q28: 2 | S28: 0 | T28: 0 | V28: 0 | W28: 0 | Y28: 0 | Z28: 0 | AB28: 22 | AC28: 14 | AE28: 0 | AF28: 0
C29: CONCIENTIZACIÓN USO DE CASCO | D29: 0 | E29: 0 | G29: 0 | H29: 0 | J29: 0 | K29: 0 | M29: 0 | N29: 0 | P29: 0 | Q29: 0 | S29: 0 | T29: 0 | V29: 1 | W29: 1 | Y29: 0 | Z29: 0 | AB29: 3 | AC29: 3 | AE29: 1 | AF29: 1
C30: AMPLIACION CARRETERA CIUIDAD HIDALGO-ZITACUARO | D30: 0 | E30: 0 | G30: 0 | H30: 0 | J30: 0 | K30: 0 | M30: 0 | N30: 0 | P30: 0 | Q30: 0 | S30: 0 | T30: 0 | V30: 0 | W30: 0 | Y30: 0 | Z30: 0 | AB30: 10 | AC30: 6 | AE30: 0 | AF30: 0
C31: SEGURIDAD EN CARRETERAS - ZINAPECUARO - MORELIA | D31: 1 | E31: 1 | G31: 0 | H31: 0 | J31: 0 | K31: 0 | M31: 0 | N31: 0 | P31: 0 | Q31: 0 | S31: 0 | T31: 0 | V31: 0 | W31: 0 | Y31: 0 | Z31: 0 | AB31: 0 | AC31: 0 | AE31: 0 | AF31: 0
C32: SEGURIDAD EN CARRETERAS - SALAMANCA - MORELIA | D32: 1 | E32: 1 | G32: 0 | H32: 0 | J32: 0 | K32: 0 | M32: 0 | N32: 0 | P32: 0 | Q32: 0 | S32: 0 | T32: 0 | V32: 0 | W32: 0 | Y32: 0 | Z32: 0 | AB32: 0 | AC32: 0 | AE32: 0 | AF32: 0
