Workbook

Sheet EST. FUR
B2: FECHA | C2: 45453 | D2: ESTADO DE FUERZA DE PERSONAL
B3: UNIDAD | C3: CATEGORIA | D3: PRESENTES | E3: FRANCOS | F3: FALTANDO | G3: CURSOS | H3: VACACIONES | I3: COMISIONADOS | J3: INCAPACIDAD | K3: PERMISO | L3: OTROS | M3: TOTAL, POR AGRUPAMIENTO
B4: SINIESTROS | C4: OPERATIVOS | D4: 18 | E4: 13 | F4: 0 | G4: 0 | H4: 3 | I4: 3 | J4: 1 | K4: 1 | L4: 0 | M4: =SUM(D4:L4) -> 39
C5: ADMINISTRATIVOS | D5: 7 | E5: 2 | F5: 0 | G5: 0 | H5: 0 | I5: 0 | J5: 0 | K5: 0 | L5: 0 | M5: =SUM(D5:L5) -> 9

Sheet EST. VEH
B2: FECHA | C2: ='EST. FUR'!$C$2 -> 45453 | D2: ESTADO DE FUERZA VEHICULAR ACTIVO
B3: ÁREA Y/O REGIÓN | C3: CHARGER | D3: FORD 150 | E3: CAMIONETA F250 | F3: RAM DODGE 1500 | G3: JEEP PATRIOT | H3: ECO SPORT | I3: TSURU | J3: PLATINA | K3: KAWASAKY KLR650 | L3: KAWASAKY ER-6N | M3: TOTAL ACTIVAS | N3: =IF(M12=M4+M8,TRUE) -> TRUE
B4: SINIESTROS | C4: 5 | D4: 0 | E4: 0 | F4: 0 | G4: 1 | H4: 0 | I4: 1 | J4: 0 | K4: 7 | L4: 0 | M4: =SUM(C4:L4) -> 14
B6: FECHA | C6: ='EST. FUR'!$C$2 -> 45453 | D6: ESTADO DE FUERZA VEHICULAR INACTIVO
B7: ÁREA Y/O REGIÓN | C7: CHARGER | D7: FORD 150 | E7: CAMIONETA F250 | F7: RAM DODGE 1500 | G7: JEEP PATRIOT | H7: ECO SPORT | I7: TSURU | J7: PLATINA | K7: KAWASAKY KLR650 | L7: KAWASAKY ER-6N | M7: TOTAL DE INACTIVAS
B8: SINIESTROS | C8: 3 | D8: 0 | E8: 0 | F8: 1 | G8: 0 | H8: 0 | I8: 0 | J8: 0 | K8: 0 | L8: 0 | M8: =SUM(C8:L8) -> 4
B10: FECHA | C10: ='EST. FUR'!$C$2 -> 45453 | D10: TOTAL DE ESTADO DE FUERZA VEHICULAR
B11: ÁREA Y/O REGIÓN | C11: CHARGER | D11: FORD 150 | E11: CAMIONETA F250 | F11: RAM DODGE 1500 | G11: JEEP PATRIOT | H11: ECO SPORT | I11: TSURU | J11: PLATINA | K11: KAWASAKY KLR650 | L11: KAWASAKY ER-6N | M11: TOTAL
B12: SINIESTROS | C12: 8 | D12: 0 | E12: 0 | F12: 1 | G12: 1 | H12: 0 | I12: 1 | J12: 0 | K12: 7 | L12: 0 | M12: =SUM(C12:L12) -> 18

Sheet ARM.
B2: FECHA | C2: ='EST. FUR'!C2 -> 45453 | D2: ESTADO DE FUERZA DE ARMAMENTO
B3: UNIDAD | C3: ARMAS | F3: MUNICIÓN | J3: DONDE SE ENCUENTRAN
C4: ARMA CORTA | D4: ARMA LARGA | E4: TOTAL | F4: CARGADORES | G4: CARTUCHOS 9mm | H4: CARTUCHOS .223 Y/O 5.56 | I4: CARTUCHOS 0.38 | J4: ASIGNADO | K4: EN DEPÓSITO | L4: TOTAL
B5: SINIESTROS | C5: 34 | D5: 22 | E5: =C5+D5 -> 56 | F5: 111 | G5: 1098 | H5: 1380 | I5: 18 | J5: 11 | K5: 45 | L5: =J5+K5 -> 56 | M5: =IF(E5=L5,TRUE) -> TRUE

Sheet CARRUSEL
B2: OPERATIVOS CARUSEL | T2: DETENIDOS
B3: REGIÓN | C3: UNIDAD | D3: DISPOSITIVOS | E3: PUESTOS DE CONTROL | F3: UBICACIÓN | G3: UNIDADES PARTICIPANTES | H3: KILOMETROS RECORRIDOS | I3: CANTIDAD DE RECORIDOS | J3: TRAMO CARRETERO | K3: ESTADO DE FUERZA | L3: TIEMPO IMPLEMENTADO | M3: APOYOS VIALES | N3: APOYO A CARAVANAS | O3: SERVICIO DE ESCOLTA | P3: CONOCIMIENTO DE REPORTES DE ROBO | Q3: ANTECEDENTES REVISADOS | R3: AMONESTACIONES VERBALES | S3: VEHÍCULOS RECUPERADOS | T3: FUERO COMÚN | U3: FUERO FEDERAL | V3: JURÍDICO
B4: MORELIA | C4: SINIESTROS
B5: =IF(D4=OPERATIVOS!E6,TRUE) -> TRUE | C5: TOTAL | Q5: =IF(Q4=OPERATIVOS!J6,TRUE) -> TRUE
B7: UBICACIÓN | C7: NOMBRE
B8: A
B9: B
B10: C
B11: D
B12: E
B13: F
B14: G
B15: H
B16: I
B17: J
B18: K
B19: L
B20: TRAMO CARRETERO | C20: NOMBRE
B21: Ñ
B22: O
B23: P
B24: Q
B25: R
B26: S
B27: T
B28: U
B29: W
B30: X
B31: Y
B32: X

Sheet OPERATIVOS
B3: TABLA DE OPERATIVOS | D3: ='EST. FUR'!C2 -> 45453 | E3: OPERATIVIDAD | K3: CORRALÓN | M3: AMONESTACIONES VERBALES | N3: VEHÍCULOS RECUPERADOS | O3: DETENIDOS
B4: UNIDAD | C4: LUGAR | D4: OPERATIVOS | E4: DISPOSITIVOS REALIZADOS | F4: DESPOLARIZADOS | G4: ANTECEDENTES REVISADOS A PERSONAS | H4: ANTECEDENTES REVISADOS A VEHÍCULOS | I4: ANTECEDENTES REVISADOS A MOTOCICLETAS | J4: TOTAL ANTECEDENTES REVISADOS | K4: VEHÍCULOS | L4: MOTOS | O4: FUERO COMÚN | P4: FUERO FEDERAL | Q4: JURÍDICO
B5: SINIESTROS | D5: RELÁMPAGO | J5: =I5+H5+G5 -> 0
B6: SINIESTROS | D6: CARRUSEL | J6: =I6+H6+G6 -> 0
B7: SINIESTROS | D7: BLINDAJE | J7: =I7+H7+G7 -> 0
B8: SINIESTROS | D8: CONCIENTIZACIÓN A MOTOCICLISTAS | J8: =I8+H8+G8 -> 0
B9: SINIESTROS | D9: PUESTO DE REVISIÓN | J9: =I9+H9+G9 -> 0
B10: SINIESTROS | D10: PUESTO DE CONTROL | J10: =I10+H10+G10 -> 0
B11: SINIESTROS | D11: APOYO COCOTRA | J11: =I11+H11+G11 -> 0
B12: SINIESTROS | D12: BLINDAJE CON ESTADOS COLINDANTES | J12: =I12+H12+G12 -> 0
B13: SINIESTROS | D13: BASES DE OPERACIONES INTERINSTITUCIONAL | J13: =I13+H13+G13 -> 0
B14: SINIESTROS | D14: OTROS OPERATIVOS (Especificar en las novedades relevantes) | J14: =I14+H14+G14 -> 0

Sheet TOTAL
C1: SINIESTROS
B2: FECHA | C2: 45497
A3: No. | B3: CATEGORÍA | C3: ACTIVIDAD | D3: CANTIDAD | E3: ESTADO DE FUERZA PARTICIPANTE | F3: UNIDADES PARTICIPANTES | G3: KILOMETROS RECORRIDOS | H3: PERSONAS ALCANZADAS | I3: RECOMENDACIONES
A4: 1 | B4: INSTITUCIONES | C4: APOYO A EVENTOS PÚBLICOS
C5: APOYO A EVENTOS DEPORTIVOS
C6: APOYO A EVENTOS CULTURALES
C7: APOYO A EVENTOS RELIGIOSOS
C8: APOYOS A OTRAS DEPENDENCIAS (Publicas o privadas)
C9: ESCUELAS
C10: DILIGENCIAS
C11: OTROS TIPOS (Especificar en las novedades relevantes)
A12: 2 | B12: REPORTES C5i | C12: OBSTRUCCIÓN DE COCHERAS
C13: OTROS TIPOS DE OBSTRUCCIÓN
C14: ACTOS DELICTIVOS
C15: SINIESTROS
C16: HECHOS DE TRÁNSITO
C17: CONSENTRACION PERSONAS
C18: OTROS REPORTES (Especificar en las novedades relevantes)
A19: 3 | B19: ABANDERAMIENTOS | C19: CORTES DE CIRCULACIÓN
C20: ACCIDENTES
C21: MARCHAS
C22: MÍTINES
C23: OBRAS PÚBLICAS
C24: ACOMPAÑAMIENTO A CARAVANAS U OTROS
C25: OTROS ABANDERAMIENTOS (Especificar en las novedades relevantes)
A26: 4 | B26: OPERATIVOS | C26: RELÁMPAGO | D26: =OPERATIVOS!E5 -> 0
C27: CARRUSEL | D27: =OPERATIVOS!E6 -> 0 | E27: =CARRUSEL!K4 -> 0 | F27: =CARRUSEL!G4 -> 0 | G27: =CARRUSEL!H4 -> 0 | I27: =CARRUSEL!R4 -> 0
C28: BLINDAJE | D28: =OPERATIVOS!E7 -> 0
C29: CONCIENTIZACIÓN USO DE CASCO | D29: =OPERATIVOS!E8 -> 0
C30: PUESTO DE REVISIÓN | D30: =OPERATIVOS!E9 -> 0
C31: PUESTO DE CONTROL | D31: =OPERATIVOS!E10 -> 0
C32: APOYO COCOTRA | D32: =OPERATIVOS!E11 -> 0
C33: BLINDAJE CON ESTADOS COLINDANTES | D33: =OPERATIVOS!E12 -> 0
C34: BASES DE OPERACIONES INTERINSTITUCIONAL | D34: =OPERATIVOS!E13 -> 0
C35: OTROS OPERATIVOS (Especificar en las novedades relevantes) | D35: =OPERATIVOS!E14 -> 0
A36: 5 | B36: PROGRAMAS | C36: CONDUCE SIN ALCOHOL (ALCOHOLÍMETRO)
C37: OTROS PROGRAMAS (Especificar en las novedades relevantes)
A38: 6 | B38: MONITOREOS | C38: VÍAS FÉRREAS
C39: PERIFÉRICOS
C40: AVENIDAS
...

Sheet NOV. REL
A1: N°. | B1: HORA | C1: LUGAR | D1: ASUNTO | E1: RESOLUCIÓN | F1: VEHÍCULOS TURNADOS, PERSONAS DETENIDAS, VEHÍCULOS RECUPERADOS (CANTIDAD Y DATOS GENERALES) | G1: GRAFICA 1 | H1: GRAFICA 2 | I1: GRAFICA 3
A2: 1 | B2: 0.89583333 | C2: Av. Escuadrón 201 y Joaquín Rivadeyra, col. Guadalupe, Morelia, Michoacán | D2: Se informa que, que se atiende hecho de transito clasificado como COLISIÓN POR NO RESPETAR SEMAFORO sin personas lesionadas, sobre Av. Escuadrón 201 y Joaquín Rivadeyra, col. Guadalupe, donde participan: MOTOCICLETA (A) Marca Vento, Modelo 2022, Tipo Trabajo, Línea Xpress 150, Color Blanco y Rojo, Placas para circular 92PMA7 del servicio particular de esta entidad federativa, Serie 3MUA0DBD4N1013905, el cual se encontraba abandonado; AUTOMOVIL (B) Marca Suzuki, Modelo 2022, Tipo Suv, Línea Ertiga, Color Plata, Placas para circular PPT854A del servicio particular de esta entidad federativa, Serie MHYNC22S0NJ11930, tarjeta de circulación a nombre de NORMA EVELIA RODRIGUEZ GERREIRA, conducido por el C. ALEJANDRO CONEJO RODRIGUEZ de 26 años de edad, con domicilio en Emilio Carranza # 633, colonia Jardines de Guadalupe, en esta ciudad, presento licencia vigente | E2: Dos vehículos fueron retirados del lugar y resguardados en el corralón de Grúas HERNANDEZ, para su puesta a disposición del Ministerio público. | F2: 2 vehiculos turnados: Marca Vento, Modelo 2022, Tipo Trabajo, Línea Xpress 150, Color Blanco y Rojo, Placas para circular 92PMA7 del servicio particular de esta entidad federativa, Serie 3MUA0DBD4N1013905; Marca Suzuki, Modelo 2022, Tipo Suv, Línea Ertiga, Color Plata, Placas para circular PPT854A del servicio particular de esta entidad federativa, Serie MHYNC22S0NJ11930
A3: 2 | B3: 0.60833333 | C3: Boulevard Agustín Arriaga Rivera y Aristeo Mercado, col. Chapultepec Sur, Morelia, Michoacán | D3: Se informa que, que se atiende hecho de transito clasificado como COLISIÓN POR CORTE DE CIRCULACIÓN sin personas lesionadas, sobre Boulevard Agustín Arriaga Rivera y Aristeo Mercado, col. Chapultepec Sur, donde participan: AUTOMOVIL (A) Marca Ford, Modelo 2008, Tipo Sedán, Línea Fiesta, Color Gris, Placas para circular NYE3710 del servicio particular del Estado de México, Serie WF0HT03482113523, tarjeta de circulación a nombre de MIGUEL ANGEL TOVAR ANAYA, conducido por el C. MARCO ANTONIO TEJADA NAVA, presentó licencia de Chofer; AUTOMOVIL (B) Marca Dodge, Modelo 2015, Tipo Suv, Línea Journey, Color Negro, Placas para circular PPG969B del servicio particular de esta entidad federativa, Serie 3C4PDCCB0FT592948, tarjeta de circulación a nombre del C. GERARDO SANCHEZ SILVA, presentó licencia de automovilista | E3: Dos vehículos fueron retirados del lugar y resguardados en el corralón de Grúas MUÑOZ, para su puesta a disposición del Ministerio público. | F3: 2 vehiculos turnados: Marca Ford, Modelo 2008, Tipo Sedán, Línea Fiesta, Color Gris, Placas para circular NYE3710 del servicio particular del Estado de México, Serie WF0HT03482113523; Marca Dodge, Modelo 2015, Tipo Suv, Línea Journey, Color Negro, Placas para circular PPG969B del servicio particular de esta entidad federativa, Serie 3C4PDCCB0FT592948
A4: 3
A5: 4
A6: 5
A7: 6
A8: 7
A9: 8
A10: 9
A11: 10
A12: 11
A13: 12

Sheet CAMPAÑAS
B2: ='EST. FUR'!C2 -> 45453 | C2: CAMPAÑAS
B3: UNIDAD | C3: CAMPAÑA CONCIENTIZACION Y PREVENCIÓN | D3: REPARTICIÓN DE TRIPTICOS | E3: ESTACIONALES (SEMANA SANTA, NAVIDAD ETC.) | F3: OTRAS (Especificar en las novedades relevantes) | G3: ELEMENTOS | H3: UNIDADES | I3: TOTAL, DE PERSONAS SENCIBILIZADAS | J3: RECOMENDACIONES
B4: SINIESTROS | C4: =TOTAL!D67 -> 0 | D4: =TOTAL!D68 -> 0 | E4: =TOTAL!D69 -> 0 | F4: =TOTAL!D70 -> 0 | G4: =SUM(TOTAL!E67:E70) -> 0 | H4: =SUM(TOTAL!F67:F70) -> 0 | I4: =SUM(TOTAL!H67:H70) -> 0 | J4: =SUM(TOTAL!I67:I70) -> 0

Sheet KILOMETRAJES
A1: ATENCIÓN A SINIESTROS KMS
E2: INI A | F2: FIN B | G2: KMS RECORR
A3: NO. | B3: ECO | C3: PLACA | D3: NIV | E3: ENTRADA | F3: FIN | G3: DIFERENCIA
A4: 1 | B4: 04-137 | C4: MC-523-A1 | D4: 2C3CDXAT6EH223637 | E4: 257244 | F4: 257244 | G4: =KILOMETRAJES!$F4-KILOMETRAJES!$E4 -> 0
A5: 2 | B5: 3208 | C5: MC865A1 | D5: 2C3CDXAG6GH205077 | E5: 275370 | F5: 275370 | G5: =KILOMETRAJES!$F5-KILOMETRAJES!$E5 -> 0
A6: 3 | B6: 3386 | C6: MC758A1 | D6: 3C6TR5DT1GG277564 | E6: 230174 | F6: 230174 | G6: =KILOMETRAJES!$F6-KILOMETRAJES!$E6 -> 0
A7: 4 | B7: 3233 | C7: MC082A2 | D7: 2C3CDXA686H211365 | E7: 0 | F7: 0 | G7: =KILOMETRAJES!$F7-KILOMETRAJES!$E7 -> 0
A8: 5 | B8: 3406 | C8: MC-753-A1 | D8: 2C3CDXAG8GH211415 | E8: 352099 | F8: 352099 | G8: =KILOMETRAJES!$F8-KILOMETRAJES!$E8 -> 0
A9: 6 | B9: 3257 | C9: MC-035-A2 | D9: 2C3CDXAG5GH211274 | E9: 325791 | F9: 325791 | G9: =KILOMETRAJES!$F9-KILOMETRAJES!$E9 -> 0
A10: 7 | B10: 3153 | C10: MC-007-A2 | D10: 2C3CDXAG8GH205291 | E10: 355109 | F10: 355226 | G10: =KILOMETRAJES!$F10-KILOMETRAJES!$E10 -> 117
A11: 8 | B11: 3190 | C11: MC376A1 | D11: 2C3CDXAGXGH205082 | E11: 256945 | F11: 256945 | G11: =KILOMETRAJES!$F11-KILOMETRAJES!$E11 -> 0
A12: 9 | B12: 3144 | C12: MC-085-A2 | D12: 2C3CDXAG5GH197084 | E12: 311411 | F12: 311567 | G12: =KILOMETRAJES!$F12-KILOMETRAJES!$E12 -> 156
A13: 10 | B13: 3165 | C13: MC-361A1 | D13: 2C3CDXAG3GH205294 | E13: 227773 | F13: 227827 | G13: =KILOMETRAJES!$F13-KILOMETRAJES!$E13 -> 54
A14: 11 | B14: 3223 | C14: MC-084-A2 | D14: 2C3CDXAG4GH211282 | E14: 169881 | F14: 169881 | G14: =KILOMETRAJES!$F14-KILOMETRAJES!$E14 -> 0
A15: 12 | B15: 3286 | C15: MC-756-A1 | D15: 2C3CDXAG3GH211337 | E15: 394568 | F15: 394660 | G15: =KILOMETRAJES!$F15-KILOMETRAJES!$E15 -> 92
A16: 13 | B16: 04-174 | C16: MC615A4 | D16: 1C4AJPAB6FD179530 | E16: 236183 | F16: 236288 | G16: =KILOMETRAJES!$F16-KILOMETRAJES!$E16 -> 105
A17: 14 | B17: 04-301 | C17: MC485A4 | D17: 3N1EB31S2EK346264 | E17: 201120 | F17: 201120 | G17: =KILOMETRAJES!$F17-KILOMETRAJES!$E17 -> 0
A18: 15 | B18: 16-726 | C18: MC14B | D18: JKAKLEE18GDA87726 | E18: 0 | F18: 0 | G18: =KILOMETRAJES!$F18-KILOMETRAJES!$E18 -> 0
A19: 16 | B19: 16-872 | C19: MC58B | D19: JKAKLEE19GDA85872 | E19: 0 | F19: 0 | G19: =KILOMETRAJES!$F19-KILOMETRAJES!$E19 -> 0
A20: 17 | B20: 16-888 | C20: MC60D | D20: JKAKLEE11GDA87888 | E20: 0 | F20: 0 | G20: =KILOMETRAJES!$F20-KILOMETRAJES!$E20 -> 0
A21: 18 | B21: 16-120 | C21: MC17B | D21: JKAKLEE10GDA86120 | E21: 0 | F21: 0 | G21: =KILOMETRAJES!$F21-KILOMETRAJES!$E21 -> 0
A22: 19 | B22: 16-889 | C22: MC89A | D22: JKAKLEE13GDA87889 | E22: 0 | F22: 0
A23: 20
G24: =KILOMETRAJES!$F24-KILOMETRAJES!$E24 -> 0
G25: =KILOMETRAJES!$F25-KILOMETRAJES!$E25 -> 0
G26: =KILOMETRAJES!$F26-KILOMETRAJES!$E26 -> 0
G27: =SUBTOTAL(109,KILOMETRAJES!$G$4:$G$26) -> 524
