Workbook

Sheet EST. FUR
B2: FECHA | C2: 46175 | D2: ESTADO DE FUERZA DE PERSONAL
B3: UNIDAD | C3: CATEGORIA | D3: PRESENTES | E3: FRANCOS | F3: FALTANDO | G3: CURSOS | H3: VACACIONES | I3: COMISIONADOS | J3: INCAPACIDAD | K3: PERMISO | L3: OTROS | M3: TOTAL, POR AGRUPAMIENTO
B4: VIALIDADES URBANAS | C4: OPERATIVOS | D4: 78 | E4: 73 | F4: 1 | G4: 7 | H4: 0 | I4: 1 | J4: 3 | K4: 1 | L4: 2 | M4: =SUM(D4:L4) -> 166
C5: ADMINISTRATIVOS | D5: 16 | E5: 4 | F5: 0 | G5: 0 | H5: 0 | I5: 0 | J5: 0 | K5: 0 | L5: 0 | M5: =SUM(D5:L5) -> 20

Sheet EST. VEH
B2: FECHA | C2: ='EST. FUR'!$C$2 -> 46175 | D2: ESTADO DE FUERZA VEHICULAR ACTIVO
B3: ÁREA Y/O REGIÓN | C3: CHARGER | D3: FORD 150 | E3: CAMIONETA F250 | F3: RAM DODGE 1500 | G3: JEEP PATRIOT | H3: ECO SPORT | I3: TSURU | J3: PLATINA | K3: KAWASAKY KLR650 | L3: KAWASAKY ER-6N | M3: TOTAL ACTIVAS | N3: =IF(M12=M4+M8,TRUE) -> TRUE
B4: VIALIDADES URBANAS | C4: 7 | D4: 1 | E4: 0 | F4: 5 | G4: 0 | H4: 1 | I4: 0 | J4: 0 | K4: 34 | L4: 39 | M4: =SUM(C4:L4) -> 87
B6: FECHA | C6: ='EST. FUR'!$C$2 -> 46175 | D6: ESTADO DE FUERZA VEHICULAR INACTIVO
B7: ÁREA Y/O REGIÓN | C7: CHARGER | D7: FORD 150 | E7: CAMIONETA F250 | F7: RAM DODGE 1500 | G7: JEEP PATRIOT | H7: ECO SPORT | I7: TSURU | J7: PLATINA | K7: KAWASAKY KLR650 | L7: KAWASAKY ER-6N | M7: TOTAL DE INACTIVAS
B8: VIALIDADES URBANAS | C8: 2 | D8: 0 | E8: 0 | F8: 0 | G8: 2 | H8: 0 | I8: 0 | J8: 0 | K8: 9 | L8: 3 | M8: =SUM(C8:L8) -> 16
B10: FECHA | C10: ='EST. FUR'!$C$2 -> 46175 | D10: TOTAL DE ESTADO DE FUERZA VEHICULAR
B11: ÁREA Y/O REGIÓN | C11: CHARGER | D11: FORD 150 | E11: CAMIONETA F250 | F11: RAM DODGE 1500 | G11: JEEP PATRIOT | H11: ECO SPORT | I11: TSURU | J11: PLATINA | K11: KAWASAKY KLR650 | L11: KAWASAKY ER-6N | M11: TOTAL
B12: VIALIDADES URBANAS | C12: 9 | D12: 1 | E12: 0 | F12: 5 | G12: 2 | H12: 1 | I12: 0 | J12: 0 | K12: 43 | L12: 42 | M12: =SUM(C12:L12) -> 103

Sheet ARM.
B2: FECHA | C2: ='EST. FUR'!C2 -> 46175 | D2: ESTADO DE FUERZA DE ARMAMENTO
B3: UNIDAD | C3: ARMAS | F3: MUNICIÓN | J3: DONDE SE ENCUENTRAN
C4: ARMA CORTA | D4: ARMA LARGA | E4: TOTAL | F4: CARGADORES | G4: CARTUCHOS 9mm | H4: CARTUCHOS .223 Y/O 5.56 | I4: CARTUCHOS 0.38 | J4: ASIGNADO | K4: EN DEPÓSITO | L4: TOTAL
B5: VIALIDADES URBANAS | C5: 99 | D5: 48 | E5: =C5+D5 -> 147 | F5: 312 | G5: 3130 | H5: 3755 | I5: 0 | J5: 147 | K5: 0 | L5: =J5+K5 -> 147 | M5: =IF(E5=L5,TRUE) -> TRUE

Sheet CARRUSEL
B2: OPERATIVOS CARUSEL | T2: DETENIDOS
B3: REGIÓN | C3: UNIDAD | D3: DISPOSITIVOS | E3: PUESTOS DE CONTROL | F3: UBICACIÓN | G3: UNIDADES PARTICIPANTES | H3: KILOMETROS RECORRIDOS | I3: CANTIDAD DE RECORIDOS | J3: TRAMO CARRETERO | K3: ESTADO DE FUERZA | L3: TIEMPO IMPLEMENTADO | M3: APOYOS VIALES | N3: APOYO A CARAVANAS | O3: SERVICIO DE ESCOLTA | P3: CONOCIMIENTO DE REPORTES DE ROBO | Q3: ANTECEDENTES REVISADOS | R3: AMONESTACIONES VERBALES | S3: VEHÍCULOS RECUPERADOS | T3: FUERO COMÚN | U3: FUERO FEDERAL | V3: JURÍDICO
B4: MORELIA | C4: VIALIDADES URBANAS | D4: 0 | E4: 0 | F4: 0 | G4: 0 | H4: 0 | I4: 0 | J4: 0 | K4: 0 | L4: 0 | M4: 0 | N4: 0 | O4: 0 | P4: 0 | Q4: 0 | R4: 0 | S4: 0 | T4: 0 | U4: 0 | V4: 0
B5: =IF(D4=OPERATIVOS!E6,TRUE) -> TRUE | C5: TOTAL | Q5: =IF(Q4=OPERATIVOS!J6,TRUE) -> TRUE
B7: UBICACIÓN | C7: NOMBRE
B8: A
B9: B
B10: C
B11: D
B12: E
B13: F
B14: G
B15: H
B16: I
B17: J
B18: K
B19: L
B20: TRAMO CARRETERO | C20: NOMBRE
B21: Ñ
B22: O
B23: P
B24: Q
B25: R
B26: S
B27: T
B28: U
B29: W
B30: X
B31: Y
B32: X

Sheet TOTAL
C1: VIALIDADES URBANAS
B2: FECHA | C2: ='EST. FUR'!C2 -> 46175
A3: No. | B3: CATEGORÍA | C3: ACTIVIDAD | D3: CANTIDAD | E3: ESTADO DE FUERZA PARTICIPANTE | F3: UNIDADES PARTICIPANTES | G3: KILOMETROS RECORRIDOS | H3: PERSONAS ALCANZADAS | I3: RECOMENDACIONES
A4: 1 | B4: INSTITUCIONES | C4: APOYO A EVENTOS PÚBLICOS
C5: APOYO A EVENTOS DEPORTIVOS
C6: APOYO A EVENTOS CULTURALES
C7: APOYO A EVENTOS RELIGIOSOS
C8: APOYOS A OTRAS DEPENDENCIAS (Publicas o privadas)
C9: ESCUELAS | D9: 8 | E9: 16 | F9: 4 | H9: 350
C10: DILIGENCIAS
C11: OTROS TIPOS (Especificar en las novedades relevantes)
A12: 2 | B12: REPORTES C5i | C12: OBSTRUCCIÓN DE COCHERAS
C13: OTROS TIPOS DE OBSTRUCCIÓN
C14: ACTOS DELICTIVOS
C15: SINIESTROS
C16: HECHOS DE TRÁNSITO
C17: CONSENTRACION PERSONAS
C18: OTROS REPORTES (Especificar en las novedades relevantes)
A19: 3 | B19: ABANDERAMIENTOS | C19: CORTES DE CIRCULACIÓN
C20: ACCIDENTES | D20: 1 | E20: 1 | F20: 1 | H20: 1
C21: MARCHAS
C22: MÍTINES
C23: OBRAS PÚBLICAS | D23: 3 | E23: 4 | F23: 3 | H23: 450
C24: ACOMPAÑAMIENTO A CARAVANAS U OTROS
C25: OTROS ABANDERAMIENTOS (Especificar en las novedades relevantes)
A26: 4 | B26: OPERATIVOS | C26: ESCUELA SEGURA | D26: 8 | E26: 16 | F26: 4 | H26: 350
C27: CONEXIÒN INSTITUCIONAL
C28: RESPUESTA VIAL INMEDIATA
C29: ABANDERAMIENTO ACTIVO | D29: 1 | E29: 1 | F29: 1 | H29: 450
C30: PASO CONTINUO | D30: 3 | E30: 11 | F30: 8 | H30: 1200
A36: 5 | B36: PROGRAMAS | C36: CONDUCE SIN ALCOHOL (ALCOHOLÍMETRO)
C37: OTROS PROGRAMAS (Especificar en las novedades relevantes)
A38: 6 | B38: MONITOREOS | C38: VÍAS FÉRREAS | D38: 1 | E38: 2 | H38: 250
C39: PERIFÉRICOS | D39: 1 | E39: 11 | F39: 10 | H39: 400
C40: AVENIDAS | D40: 11 | E40: 8 | F40: 10 | H40: 250
C41: TIENDAS DEPARTAMENTALES
C42: BANCOS | D42: 7 | E42: 2 | H42: 300
C43: GASOLINERAS
C44: OFICINAS GUBERNAMENTALES
C45: MANIFESTACIONES | D45: 1 | E45: 3 | F45: 3 | H45: 30
...

Sheet NOV. REL
A1: No. | B1: HORA | C1: LUGAR | D1: ASUNTO | E1: RESOLUCIÓN | F1: VEHÍCULOS TURNADOS, PERSONAS DETENIDAS, VEHÍCULOS RECUPERADOS (CANTIDAD Y DATOS GENERALES) | G1: GRAFICA 1 | H1: GRAFICA 2 | I1: Grafica 3
A2: 1 | B2: 17:05 hrs. | C2: Morelia | D2: ABANDERAMIENTOS (OBRAS PÚBLICAS) | E2: Continúa el apoyo al C. Carlos Tovar Pedraza, Supervisor del MOREBÚS, en la avenida Francisco I. Madero Poniente, esquina con avenida Cointzio. CORTES DE CIRCULACIÓN Carril lateral de extrema izquierda de la avenida Francisco I. Madero Poniente, esquina con avenida Cointzio, en sentido poniente-oriente, donde se realizarán obras correspondientes al proyecto MOREBÚS. | F2: Sin novedad
A3: 2 | B3: 19:53 hrs. | C3: Morelia | D3: ABANDERAMIENTOS (OBRAS PÚBLICAS) | E3: Se mantiene cerrada la lateral de Paseo de la República, en el Sector Revolución, por tiempo indefinido, debido a trabajos de obra en la vialidad, consistentes en la apertura del suelo a lo largo de toda la calle. • Como vía alterna para acceder al Mercado de Abastos, se recomienda utilizar la calle Rafael Galván. • Hasta el momento, se registra presencia de lluvia en la zona. | F3: Sin novedad
B4: 07:22 hrs. | C4: Morelia | D4: ABANDERAMIENTOS (OBRAS PÚBLICAS) | E4: Se inicia con el dispositivo de vialidad y abanderamiento sobre el Periférico Revolución, a la altura del Mercado de Abastos (Puente Eréndira), en el sentido de salida a Charo hacia la salida a Salamanca, donde se llevan a cabo trabajos de habilitación de carril lateral por parte de la empresa constructora SUPRA, bajo la responsabilidad del Ing. Michel Ramírez. Permanecemos en el lugar brindando seguridad vial y apoyo a los trabajadores durante la ejecución de las labores. | F4: Sin novedad
B5: 07:36 a 10:12 hrs. | C5: Morelia | D5: MONITOREOS (MANIFESTACIONES) | E5: Se instala dispositivo de vialidad sobre Periférico y Raza Maya para efectuar los cortes de circulación necesarios, derivado de una manifestación y bloqueo vial realizado por aproximadamente 30 personas, integrantes de las colonias Precursores de la Revolución, Jesús Romero Flores, 3 de Agosto, Felipe Carrillo Puerto, Primo Tapia y Los Ángeles. Los manifestantes solicitan el suministro de agua potable y portan pancartas con las siguientes consignas: "OOAPAS, el pago está al día; el servicio es una deuda con nosotros." "El agua es un derecho, no un lujo." "Exigimos agua por la red en días fijos." "Ponte a trabajar, ya que no queremos más mentiras." "Basta de mentiras, Adolfo 'Fito' Torres." | F5: Concluye el dispositivo de abanderamoento, sin novedad.
B6: 8:22 hrs. | C6: Morelia | D6: ABANDERAMIENTOS (ACCIDENTES) | E6: Se abandera "SINIESTRO VIAL"; sobre Periférico a la altura del Cárcamo por lo que se implementa de inmediato Apoyo para brindar abanderamiento a los vehículos afectados en el lugar. VEHÍCULO 1 MARCA: Nissan LÍNEA: X-Trail COLOR: Rojo PLACAS: PTR-103-A CONDUCTOR: José Luis Aguirre VEHÍCULO 2 MARCA: Honda COLOR: Negra PLACAS: 41-PSA-5 CONDUCTOR: Orlando Reyes León Arriba la unidad 22-4926 a cargo Alonso Jesús Abado Hernández atiende el Siniestro Vial. | F6: Sin novedad
B7: 09:20 hrs. | C7: Morelia | D7: AUXILIO VIAL A CONDUCTORES (FALLAS MECÁNICAS) | E7: Se brinda apoyo a un vehículo descompuesto sobre Calzada Juárez y Solidaridad, realizando las maniobras necesarias para orillarlo y liberar la circulación, con el fin de agilizar el flujo vehicular y salvaguardar la integridad del conductor. Se trata de un vehículo marca Jeep, tipo Compass, color gris, con placas de circulación 403-XWR, conducido por el C. Adolfo Emilio Rosales Cortés. Una vez concluido el apoyo, el conductor agradece la atención brindada. | F7: Sin novedad
B8: 09:40 hrs. | C8: Morelia | D8: PROXIMIDAD SOCIAL (PREVENCIÓN SOCIAL) | E8: Se atiende reporte ciudadano sobre un masculino que, presuntamente, se encontraba jaloneando a una joven en la Cerrada de San Agustín, a la altura de la paletería Tocumbo. Al arribar al lugar, el masculino ya se había retirado. Entrevistada la C. Jaqueline N., manifestó que se trató únicamente de una discusión con su pareja sentimental. Tras verificar la situación, no se detectaron mayores incidencias. La entrevistada agradeció el apoyo brindado, quedando el lugar sin novedad. | F8: Sin novedad
B9: 17:00 A 17:00 hrs. | C9: Morelia | D9: DISPOSITIVO DE VIALIDAD (APOYO A LA VIALIDAD) | E9: Se continua con los dispositivos de Vialidad, en Casa Michoacán, Palacio de Gobierno, S.S.P., con la finalidad de mantener fluida la circulación. | F9: Concluye sin novedad.
B10: 17:00 A 17:00 hrs. | C10: Morelia | D10: DISPOSITIVO DE VIALIDAD (APOYO A LA VIALIDAD) | E10: Se continua con los dispositivos de Vialidad, en Avenida Camelinas, Tres Poderes, Manantiales, la Pepsi, Salida a Quiroga, Av., Siervo de la Nación, Av. La Huerta. | F10: Concluye sin novedad.
B11: 17:00 A 17:00 has. | C11: Morelia | D11: DISPOSITIVO DE VIALIDAD (APOYO A LA VIALIDAD) | E11: Se continua con los dispositivos de Vialidad, en apoyo al paso de funcionarios en diferentes puntos de la Ciudad de Morelia. | F11: Concluye sin novedad.
B12: 17:00 A 17:00 has. | C12: Morelia | D12: DISPOSITIVO DE VIALIDAD (APOYO A LA VIALIDAD) | E12: Se continua con los dispositivos de Vialidad, con recorridos de prevención en la zona bancaria del Centro Histórico, con la finalidad de disminuir el indicie delictivo de robo a cuenta habientes. | F12: Concluye sin novedad.
B13: 17:00 A 17:00 has. | C13: Morelia | D13: DISPOSITIVO DE VIALIDAD (APOYO A LA VIALIDAD) | E13: Se continua con los dispositivos de Vialidad, apoyo a cruce seguro a personas de la tercera edad, en Avenidas con mua afluencia vehicular. | F13: Concluye sin novedad.
B14: 17:00 a 17:00 has. | C14: Morelia | D14: INSTITUCIONES (ESCUELAS | E14: Durante dispositivos de vialidad en el centro de la ciudad se cuida de la seguridad y respeto de las personas peatonas, senescentes, con discapacidad, con movilidad limitada, estudiantes, ciclistas y conductoras de vehículos no motorizados en las vías públicas y estatales de comunicación, dándoles siempre preferencia sobre los vehículos. | F14: Concluye sin novedad
B15: 17:00 A 17:00 has. | C15: Morelia | D15: DISPOSITIVO DE VIALIDAD (APOYO A LA VIALIDAD) | E15: Se continua con los dispositivos de Vialidad, con recorridos de proximidad en las plazas publicas del Centro del Centro Histórico. | F15: Concluye sin novedad.

Sheet OPERATIVOS
B3: TABLA DE OPERATIVOS | D3: ='EST. FUR'!C2 -> 46175 | E3: OPERATIVIDAD | K3: CORRALÓN | M3: AMONESTACIONES VERBALES | N3: VEHÍCULOS RECUPERADOS | O3: DETENIDOS
B4: UNIDAD | C4: LUGAR | D4: OPERATIVOS | E4: DISPOSITIVOS REALIZADOS | F4: DESPOLARIZADOS | G4: ANTECEDENTES REVISADOS A PERSONAS | H4: ANTECEDENTES REVISADOS A VEHÍCULOS | I4: ANTECEDENTES REVISADOS A MOTOCICLETAS | J4: TOTAL ANTECEDENTES REVISADOS | K4: VEHÍCULOS | L4: MOTOS | O4: FUERO COMÚN | P4: FUERO FEDERAL | Q4: JURÍDICO
B5: VIALIDADES URBANAS | D5: RELÁMPAGO | E5: 0 | F5: 0 | G5: 0 | H5: 0 | I5: 0 | J5: =I5+H5+G5 -> 0
B6: VIALIDADES URBANAS | D6: CARRUSEL | E6: 0 | F6: 0 | G6: 0 | H6: 0 | I6: 0 | J6: =I6+H6+G6 -> 0
B7: VIALIDADES URBANAS | D7: BLINDAJE | E7: 0 | F7: 0 | G7: 0 | H7: 0 | I7: 0 | J7: =I7+H7+G7 -> 0
B8: VIALIDADES URBANAS | D8: CONCIENTIZACIÓN A MOTOCICLISTAS | E8: 0 | F8: 0 | G8: 0 | H8: 0 | I8: 0 | J8: =I8+H8+G8 -> 0
B9: VIALIDADES URBANAS | D9: PUESTO DE REVISIÓN | E9: 0 | F9: 0 | G9: 0 | H9: 0 | I9: 0 | J9: =I9+H9+G9 -> 0
B10: VIALIDADES URBANAS | D10: PUESTO DE CONTROL | E10: 0 | F10: 0 | G10: 0 | H10: 0 | I10: 0 | J10: =I10+H10+G10 -> 0
B11: VIALIDADES URBANAS | D11: APOYO COCOTRA | E11: 0 | F11: 0 | G11: 0 | H11: 0 | I11: 0 | J11: =I11+H11+G11 -> 0
B12: VIALIDADES URBANAS | D12: BLINDAJE CON ESTADOS COLINDANTES | E12: 0 | F12: 0 | G12: 0 | H12: 0 | I12: 0 | J12: =I12+H12+G12 -> 0
B13: VIALIDADES URBANAS | D13: BASES DE OPERACIONES INTERINSTITUCIONAL | E13: 0 | F13: 0 | G13: 0 | H13: 0 | I13: 0 | J13: =I13+H13+G13 -> 0
B14: VIALIDADES URBANAS | D14: USDA | E14: 0 | F14: 0 | G14: 0 | H14: 0 | I14: 0 | J14: =I14+H14+G14 -> 0

Sheet CAMPAÑAS
B2: ='EST. FUR'!C2 -> 46175 | C2: CAMPAÑAS
B3: UNIDAD | C3: CAMPAÑA CONCIENTIZACION Y PREVENCIÓN | D3: REPARTICIÓN DE TRIPTICOS | E3: ESTACIONALES (SEMANA SANTA, NAVIDAD ETC.) | F3: OTRAS (Especificar en las novedades relevantes) | G3: ELEMENTOS | H3: UNIDADES | I3: TOTAL, DE PERSONAS SENCIBILIZADAS | J3: RECOMENDACIONES
B4: VIALIDADES URBANAS | C4: =TOTAL!D67 -> 0 | D4: =TOTAL!D68 -> 0 | E4: =TOTAL!D69 -> 0 | F4: =TOTAL!D70 -> 0 | G4: =SUM(TOTAL!E67:E70) -> 0 | H4: =SUM(TOTAL!F67:F70) -> 0 | I4: =SUM(TOTAL!H67:H70) -> 0 | J4: =SUM(TOTAL!I67:I70) -> 0
